{
 "cells": [
  {
   "cell_type": "code",
   "execution_count": 1,
   "id": "03420c83-3d21-4f9c-8aaa-8854292fdade",
   "metadata": {},
   "outputs": [
    {
     "name": "stdout",
     "output_type": "stream",
     "text": [
      "Requirement already satisfied: docling in c:\\users\\wurfil\\appdata\\local\\programs\\python\\python311\\lib\\site-packages (2.4.1)\n",
      "Requirement already satisfied: beautifulsoup4<5.0.0,>=4.12.3 in c:\\users\\wurfil\\appdata\\local\\programs\\python\\python311\\lib\\site-packages (from docling) (4.12.3)\n",
      "Requirement already satisfied: certifi>=2024.7.4 in c:\\users\\wurfil\\appdata\\local\\programs\\python\\python311\\lib\\site-packages (from docling) (2024.8.30)\n",
      "Requirement already satisfied: deepsearch-glm<0.27.0,>=0.26.1 in c:\\users\\wurfil\\appdata\\local\\programs\\python\\python311\\lib\\site-packages (from docling) (0.26.1)\n",
      "Requirement already satisfied: docling-core<3.0.0,>=2.3.0 in c:\\users\\wurfil\\appdata\\local\\programs\\python\\python311\\lib\\site-packages (from docling) (2.3.1)\n",
      "Requirement already satisfied: docling-ibm-models<3.0.0,>=2.0.3 in c:\\users\\wurfil\\appdata\\local\\programs\\python\\python311\\lib\\site-packages (from docling) (2.0.3)\n",
      "Requirement already satisfied: docling-parse<3.0.0,>=2.0.2 in c:\\users\\wurfil\\appdata\\local\\programs\\python\\python311\\lib\\site-packages (from docling) (2.0.3)\n",
      "Requirement already satisfied: easyocr<2.0,>=1.7 in c:\\users\\wurfil\\appdata\\local\\programs\\python\\python311\\lib\\site-packages (from docling) (1.7.2)\n",
      "Requirement already satisfied: filetype<2.0.0,>=1.2.0 in c:\\users\\wurfil\\appdata\\local\\programs\\python\\python311\\lib\\site-packages (from docling) (1.2.0)\n",
      "Requirement already satisfied: huggingface_hub<1,>=0.23 in c:\\users\\wurfil\\appdata\\local\\programs\\python\\python311\\lib\\site-packages (from docling) (0.26.2)\n",
      "Requirement already satisfied: marko<3.0.0,>=2.1.2 in c:\\users\\wurfil\\appdata\\local\\programs\\python\\python311\\lib\\site-packages (from docling) (2.1.2)\n",
      "Requirement already satisfied: pandas<3.0.0,>=2.1.4 in c:\\users\\wurfil\\appdata\\local\\programs\\python\\python311\\lib\\site-packages (from docling) (2.2.2)\n",
      "Requirement already satisfied: pyarrow<17.0.0,>=16.1.0 in c:\\users\\wurfil\\appdata\\local\\programs\\python\\python311\\lib\\site-packages (from docling) (16.1.0)\n",
      "Requirement already satisfied: pydantic<3.0.0,>=2.0.0 in c:\\users\\wurfil\\appdata\\local\\programs\\python\\python311\\lib\\site-packages (from docling) (2.9.2)\n",
      "Requirement already satisfied: pydantic-settings<3.0.0,>=2.3.0 in c:\\users\\wurfil\\appdata\\local\\programs\\python\\python311\\lib\\site-packages (from docling) (2.6.1)\n",
      "Requirement already satisfied: pypdfium2<5.0.0,>=4.30.0 in c:\\users\\wurfil\\appdata\\local\\programs\\python\\python311\\lib\\site-packages (from docling) (4.30.0)\n",
      "Requirement already satisfied: python-docx<2.0.0,>=1.1.2 in c:\\users\\wurfil\\appdata\\local\\programs\\python\\python311\\lib\\site-packages (from docling) (1.1.2)\n",
      "Requirement already satisfied: python-pptx<2.0.0,>=1.0.2 in c:\\users\\wurfil\\appdata\\local\\programs\\python\\python311\\lib\\site-packages (from docling) (1.0.2)\n",
      "Requirement already satisfied: requests<3.0.0,>=2.32.3 in c:\\users\\wurfil\\appdata\\local\\programs\\python\\python311\\lib\\site-packages (from docling) (2.32.3)\n",
      "Requirement already satisfied: rtree<2.0.0,>=1.3.0 in c:\\users\\wurfil\\appdata\\local\\programs\\python\\python311\\lib\\site-packages (from docling) (1.3.0)\n",
      "Requirement already satisfied: scipy<2.0.0,>=1.14.1 in c:\\users\\wurfil\\appdata\\local\\programs\\python\\python311\\lib\\site-packages (from docling) (1.14.1)\n",
      "Requirement already satisfied: typer<0.13.0,>=0.12.5 in c:\\users\\wurfil\\appdata\\local\\programs\\python\\python311\\lib\\site-packages (from docling) (0.12.5)\n",
      "Requirement already satisfied: soupsieve>1.2 in c:\\users\\wurfil\\appdata\\local\\programs\\python\\python311\\lib\\site-packages (from beautifulsoup4<5.0.0,>=4.12.3->docling) (2.5)\n",
      "Requirement already satisfied: docutils!=0.21 in c:\\users\\wurfil\\appdata\\local\\programs\\python\\python311\\lib\\site-packages (from deepsearch-glm<0.27.0,>=0.26.1->docling) (0.21.2)\n",
      "Requirement already satisfied: numpy<2.0.0,>=1.26.4 in c:\\users\\wurfil\\appdata\\local\\programs\\python\\python311\\lib\\site-packages (from deepsearch-glm<0.27.0,>=0.26.1->docling) (1.26.4)\n",
      "Requirement already satisfied: python-dotenv<2.0.0,>=1.0.0 in c:\\users\\wurfil\\appdata\\local\\programs\\python\\python311\\lib\\site-packages (from deepsearch-glm<0.27.0,>=0.26.1->docling) (1.0.1)\n",
      "Requirement already satisfied: pywin32<308,>=307 in c:\\users\\wurfil\\appdata\\local\\programs\\python\\python311\\lib\\site-packages (from deepsearch-glm<0.27.0,>=0.26.1->docling) (307)\n",
      "Requirement already satisfied: rich<14.0.0,>=13.7.0 in c:\\users\\wurfil\\appdata\\local\\programs\\python\\python311\\lib\\site-packages (from deepsearch-glm<0.27.0,>=0.26.1->docling) (13.7.1)\n",
      "Requirement already satisfied: tabulate>=0.8.9 in c:\\users\\wurfil\\appdata\\local\\programs\\python\\python311\\lib\\site-packages (from deepsearch-glm<0.27.0,>=0.26.1->docling) (0.9.0)\n",
      "Requirement already satisfied: tqdm<5.0.0,>=4.64.0 in c:\\users\\wurfil\\appdata\\local\\programs\\python\\python311\\lib\\site-packages (from deepsearch-glm<0.27.0,>=0.26.1->docling) (4.66.4)\n",
      "Requirement already satisfied: jsonref<2.0.0,>=1.1.0 in c:\\users\\wurfil\\appdata\\local\\programs\\python\\python311\\lib\\site-packages (from docling-core<3.0.0,>=2.3.0->docling) (1.1.0)\n",
      "Requirement already satisfied: jsonschema<5.0.0,>=4.16.0 in c:\\users\\wurfil\\appdata\\local\\programs\\python\\python311\\lib\\site-packages (from docling-core<3.0.0,>=2.3.0->docling) (4.22.0)\n",
      "Requirement already satisfied: pillow<11.0.0,>=10.3.0 in c:\\users\\wurfil\\appdata\\local\\programs\\python\\python311\\lib\\site-packages (from docling-core<3.0.0,>=2.3.0->docling) (10.3.0)\n",
      "Requirement already satisfied: jsonlines<4.0.0,>=3.1.0 in c:\\users\\wurfil\\appdata\\local\\programs\\python\\python311\\lib\\site-packages (from docling-ibm-models<3.0.0,>=2.0.3->docling) (3.1.0)\n",
      "Requirement already satisfied: lxml<5.0.0,>=4.9.1 in c:\\users\\wurfil\\appdata\\local\\programs\\python\\python311\\lib\\site-packages (from docling-ibm-models<3.0.0,>=2.0.3->docling) (4.9.4)\n",
      "Requirement already satisfied: mean_average_precision<2022.0.0.0,>=2021.4.26.0 in c:\\users\\wurfil\\appdata\\local\\programs\\python\\python311\\lib\\site-packages (from docling-ibm-models<3.0.0,>=2.0.3->docling) (2021.4.26.0)\n",
      "Requirement already satisfied: opencv-python-headless<5.0.0.0,>=4.6.0.66 in c:\\users\\wurfil\\appdata\\local\\programs\\python\\python311\\lib\\site-packages (from docling-ibm-models<3.0.0,>=2.0.3->docling) (4.10.0.84)\n",
      "Requirement already satisfied: torch<3.0.0,>=2.2.2 in c:\\users\\wurfil\\appdata\\local\\programs\\python\\python311\\lib\\site-packages (from docling-ibm-models<3.0.0,>=2.0.3->docling) (2.4.1+cu121)\n",
      "Requirement already satisfied: torchvision<1,>=0 in c:\\users\\wurfil\\appdata\\local\\programs\\python\\python311\\lib\\site-packages (from docling-ibm-models<3.0.0,>=2.0.3->docling) (0.19.1+cu121)\n",
      "Requirement already satisfied: scikit-image in c:\\users\\wurfil\\appdata\\local\\programs\\python\\python311\\lib\\site-packages (from easyocr<2.0,>=1.7->docling) (0.24.0)\n",
      "Requirement already satisfied: python-bidi in c:\\users\\wurfil\\appdata\\local\\programs\\python\\python311\\lib\\site-packages (from easyocr<2.0,>=1.7->docling) (0.6.3)\n",
      "Requirement already satisfied: PyYAML in c:\\users\\wurfil\\appdata\\local\\programs\\python\\python311\\lib\\site-packages (from easyocr<2.0,>=1.7->docling) (6.0.1)\n",
      "Requirement already satisfied: Shapely in c:\\users\\wurfil\\appdata\\local\\programs\\python\\python311\\lib\\site-packages (from easyocr<2.0,>=1.7->docling) (2.0.6)\n",
      "Requirement already satisfied: pyclipper in c:\\users\\wurfil\\appdata\\local\\programs\\python\\python311\\lib\\site-packages (from easyocr<2.0,>=1.7->docling) (1.3.0.post6)\n",
      "Requirement already satisfied: ninja in c:\\users\\wurfil\\appdata\\local\\programs\\python\\python311\\lib\\site-packages (from easyocr<2.0,>=1.7->docling) (1.11.1.1)\n",
      "Requirement already satisfied: filelock in c:\\users\\wurfil\\appdata\\local\\programs\\python\\python311\\lib\\site-packages (from huggingface_hub<1,>=0.23->docling) (3.14.0)\n",
      "Requirement already satisfied: fsspec>=2023.5.0 in c:\\users\\wurfil\\appdata\\local\\programs\\python\\python311\\lib\\site-packages (from huggingface_hub<1,>=0.23->docling) (2024.5.0)\n",
      "Requirement already satisfied: packaging>=20.9 in c:\\users\\wurfil\\appdata\\local\\programs\\python\\python311\\lib\\site-packages (from huggingface_hub<1,>=0.23->docling) (24.0)\n",
      "Requirement already satisfied: typing-extensions>=3.7.4.3 in c:\\users\\wurfil\\appdata\\local\\programs\\python\\python311\\lib\\site-packages (from huggingface_hub<1,>=0.23->docling) (4.12.0)\n",
      "Requirement already satisfied: python-dateutil>=2.8.2 in c:\\users\\wurfil\\appdata\\local\\programs\\python\\python311\\lib\\site-packages (from pandas<3.0.0,>=2.1.4->docling) (2.9.0.post0)\n",
      "Requirement already satisfied: pytz>=2020.1 in c:\\users\\wurfil\\appdata\\local\\programs\\python\\python311\\lib\\site-packages (from pandas<3.0.0,>=2.1.4->docling) (2024.1)\n",
      "Requirement already satisfied: tzdata>=2022.7 in c:\\users\\wurfil\\appdata\\local\\programs\\python\\python311\\lib\\site-packages (from pandas<3.0.0,>=2.1.4->docling) (2024.1)\n",
      "Requirement already satisfied: annotated-types>=0.6.0 in c:\\users\\wurfil\\appdata\\local\\programs\\python\\python311\\lib\\site-packages (from pydantic<3.0.0,>=2.0.0->docling) (0.7.0)\n",
      "Requirement already satisfied: pydantic-core==2.23.4 in c:\\users\\wurfil\\appdata\\local\\programs\\python\\python311\\lib\\site-packages (from pydantic<3.0.0,>=2.0.0->docling) (2.23.4)\n",
      "Requirement already satisfied: XlsxWriter>=0.5.7 in c:\\users\\wurfil\\appdata\\local\\programs\\python\\python311\\lib\\site-packages (from python-pptx<2.0.0,>=1.0.2->docling) (3.2.0)\n",
      "Requirement already satisfied: charset-normalizer<4,>=2 in c:\\users\\wurfil\\appdata\\local\\programs\\python\\python311\\lib\\site-packages (from requests<3.0.0,>=2.32.3->docling) (3.3.2)\n",
      "Requirement already satisfied: idna<4,>=2.5 in c:\\users\\wurfil\\appdata\\local\\programs\\python\\python311\\lib\\site-packages (from requests<3.0.0,>=2.32.3->docling) (3.7)\n",
      "Requirement already satisfied: urllib3<3,>=1.21.1 in c:\\users\\wurfil\\appdata\\local\\programs\\python\\python311\\lib\\site-packages (from requests<3.0.0,>=2.32.3->docling) (2.2.1)\n",
      "Requirement already satisfied: click>=8.0.0 in c:\\users\\wurfil\\appdata\\local\\programs\\python\\python311\\lib\\site-packages (from typer<0.13.0,>=0.12.5->docling) (8.1.7)\n",
      "Requirement already satisfied: shellingham>=1.3.0 in c:\\users\\wurfil\\appdata\\local\\programs\\python\\python311\\lib\\site-packages (from typer<0.13.0,>=0.12.5->docling) (1.5.4)\n",
      "Requirement already satisfied: colorama in c:\\users\\wurfil\\appdata\\local\\programs\\python\\python311\\lib\\site-packages (from click>=8.0.0->typer<0.13.0,>=0.12.5->docling) (0.4.6)\n",
      "Requirement already satisfied: attrs>=19.2.0 in c:\\users\\wurfil\\appdata\\local\\programs\\python\\python311\\lib\\site-packages (from jsonlines<4.0.0,>=3.1.0->docling-ibm-models<3.0.0,>=2.0.3->docling) (23.2.0)\n",
      "Requirement already satisfied: jsonschema-specifications>=2023.03.6 in c:\\users\\wurfil\\appdata\\local\\programs\\python\\python311\\lib\\site-packages (from jsonschema<5.0.0,>=4.16.0->docling-core<3.0.0,>=2.3.0->docling) (2023.12.1)\n",
      "Requirement already satisfied: referencing>=0.28.4 in c:\\users\\wurfil\\appdata\\local\\programs\\python\\python311\\lib\\site-packages (from jsonschema<5.0.0,>=4.16.0->docling-core<3.0.0,>=2.3.0->docling) (0.35.1)\n",
      "Requirement already satisfied: rpds-py>=0.7.1 in c:\\users\\wurfil\\appdata\\local\\programs\\python\\python311\\lib\\site-packages (from jsonschema<5.0.0,>=4.16.0->docling-core<3.0.0,>=2.3.0->docling) (0.18.1)\n",
      "Requirement already satisfied: six>=1.5 in c:\\users\\wurfil\\appdata\\local\\programs\\python\\python311\\lib\\site-packages (from python-dateutil>=2.8.2->pandas<3.0.0,>=2.1.4->docling) (1.16.0)\n",
      "Requirement already satisfied: markdown-it-py>=2.2.0 in c:\\users\\wurfil\\appdata\\local\\programs\\python\\python311\\lib\\site-packages (from rich<14.0.0,>=13.7.0->deepsearch-glm<0.27.0,>=0.26.1->docling) (3.0.0)\n",
      "Requirement already satisfied: pygments<3.0.0,>=2.13.0 in c:\\users\\wurfil\\appdata\\local\\programs\\python\\python311\\lib\\site-packages (from rich<14.0.0,>=13.7.0->deepsearch-glm<0.27.0,>=0.26.1->docling) (2.18.0)\n",
      "Requirement already satisfied: sympy in c:\\users\\wurfil\\appdata\\local\\programs\\python\\python311\\lib\\site-packages (from torch<3.0.0,>=2.2.2->docling-ibm-models<3.0.0,>=2.0.3->docling) (1.12)\n",
      "Requirement already satisfied: networkx in c:\\users\\wurfil\\appdata\\local\\programs\\python\\python311\\lib\\site-packages (from torch<3.0.0,>=2.2.2->docling-ibm-models<3.0.0,>=2.0.3->docling) (3.3)\n",
      "Requirement already satisfied: jinja2 in c:\\users\\wurfil\\appdata\\local\\programs\\python\\python311\\lib\\site-packages (from torch<3.0.0,>=2.2.2->docling-ibm-models<3.0.0,>=2.0.3->docling) (3.1.4)\n",
      "Requirement already satisfied: imageio>=2.33 in c:\\users\\wurfil\\appdata\\local\\programs\\python\\python311\\lib\\site-packages (from scikit-image->easyocr<2.0,>=1.7->docling) (2.36.0)\n",
      "Requirement already satisfied: tifffile>=2022.8.12 in c:\\users\\wurfil\\appdata\\local\\programs\\python\\python311\\lib\\site-packages (from scikit-image->easyocr<2.0,>=1.7->docling) (2024.9.20)\n",
      "Requirement already satisfied: lazy-loader>=0.4 in c:\\users\\wurfil\\appdata\\local\\programs\\python\\python311\\lib\\site-packages (from scikit-image->easyocr<2.0,>=1.7->docling) (0.4)\n",
      "Requirement already satisfied: mdurl~=0.1 in c:\\users\\wurfil\\appdata\\local\\programs\\python\\python311\\lib\\site-packages (from markdown-it-py>=2.2.0->rich<14.0.0,>=13.7.0->deepsearch-glm<0.27.0,>=0.26.1->docling) (0.1.2)\n",
      "Requirement already satisfied: MarkupSafe>=2.0 in c:\\users\\wurfil\\appdata\\local\\programs\\python\\python311\\lib\\site-packages (from jinja2->torch<3.0.0,>=2.2.2->docling-ibm-models<3.0.0,>=2.0.3->docling) (2.1.5)\n",
      "Requirement already satisfied: mpmath>=0.19 in c:\\users\\wurfil\\appdata\\local\\programs\\python\\python311\\lib\\site-packages (from sympy->torch<3.0.0,>=2.2.2->docling-ibm-models<3.0.0,>=2.0.3->docling) (1.3.0)\n"
     ]
    },
    {
     "name": "stderr",
     "output_type": "stream",
     "text": [
      "\n",
      "[notice] A new release of pip is available: 24.2 -> 24.3.1\n",
      "[notice] To update, run: python.exe -m pip install --upgrade pip\n"
     ]
    }
   ],
   "source": [
    "!pip install docling"
   ]
  },
  {
   "cell_type": "code",
   "execution_count": 1,
   "id": "026796d6-377d-427e-852d-511a896ab5f5",
   "metadata": {},
   "outputs": [],
   "source": [
    "from docling.backend.pypdfium2_backend import PyPdfiumDocumentBackend\n",
    "from docling.datamodel.base_models import InputFormat\n",
    "from docling.datamodel.pipeline_options import PdfPipelineOptions\n",
    "from docling.document_converter import DocumentConverter, PdfFormatOption\n",
    "from docling.models.tesseract_ocr_cli_model import TesseractCliOcrOptions\n",
    "from docling.models.tesseract_ocr_model import TesseractOcrOptions\n",
    "from docling_core.types.doc import ImageRefMode, PictureItem, TableItem, TextItem\n",
    "\n",
    "pipeline_options = PdfPipelineOptions()\n",
    "\n",
    "pipeline_options.generate_table_images = True\n",
    "pipeline_options.generate_picture_images = True\n",
    "pipeline_options.do_table_structure = True\n",
    "pipeline_options.do_ocr = False\n",
    "pipeline_options.table_structure_options.do_cell_matching = False\n",
    "\n",
    "\n",
    "doc_converter = DocumentConverter(\n",
    "    format_options={\n",
    "        InputFormat.PDF: PdfFormatOption(pipeline_options=pipeline_options)\n",
    "    }\n",
    ")"
   ]
  },
  {
   "cell_type": "code",
   "execution_count": 2,
   "id": "d375d805-000f-43eb-ad02-ddbd7ebc9986",
   "metadata": {},
   "outputs": [],
   "source": [
    "import os\n",
    "\n",
    "def definition_data(element, current_page_data):\n",
    "    if isinstance(element, TableItem):\n",
    "        current_page_data['tables'].append(element)\n",
    "    if isinstance(element, TextItem):\n",
    "        current_page_data['texts'].append(element)\n",
    "    return current_page_data\n",
    "\n",
    "def transform_data(current_page_data):\n",
    "    row = {\n",
    "        'document': '',\n",
    "        'page_num': '',\n",
    "        'table_markdown': '',\n",
    "        'text': '',\n",
    "    }\n",
    "    for table in current_page_data['tables']:\n",
    "        row['table_markdown'] = table.export_to_markdown()\n",
    "    pharagraph = []\n",
    "\n",
    "    for text in current_page_data['texts']:\n",
    "        if text.label != 'page_footer':\n",
    "            pharagraph.append(text.text)\n",
    "\n",
    "    pharagraph.append(row['table_markdown'])\n",
    "    row['text'] = '\\n'.join(pharagraph)\n",
    "\n",
    "    return row\n",
    "\n",
    "def get_data(conv_res):\n",
    "    rows = []\n",
    "    current_page_number = 1\n",
    "    current_page_data = {\n",
    "        'tables': [],\n",
    "        'texts': [],\n",
    "    }\n",
    "    \n",
    "    for element, _level in conv_res.document.iterate_items():\n",
    "        new_page_number = element.prov[0].page_no\n",
    "        if new_page_number != current_page_number:\n",
    "            row = transform_data(current_page_data)\n",
    "            row['document'] = conv_res.input.file.name  # Исправлено с result на conv_res\n",
    "            row['page_num'] = current_page_number\n",
    "\n",
    "            rows.append(row)\n",
    "            current_page_number = new_page_number\n",
    "            current_page_data = {\n",
    "                'tables': [],\n",
    "                'texts': [],\n",
    "            }\n",
    "        current_page_data = definition_data(element, current_page_data)\n",
    "    \n",
    "    # Добавляем обработку последней страницы\n",
    "    row = transform_data(current_page_data)\n",
    "    row['document'] = conv_res.input.file.name\n",
    "    row['page_num'] = current_page_number\n",
    "    rows.append(row)\n",
    "    \n",
    "    return rows\n",
    "\n",
    "rows = []\n",
    "\n",
    "import os\n",
    "from multiprocessing import Pool, Manager\n",
    "from functools import partial\n",
    "from tqdm import tqdm\n",
    "\n",
    "def proccessDoc(shared_rows, input_doc_path, file_name):\n",
    "    try:\n",
    "        conv_result = doc_converter.convert(input_doc_path)\n",
    "        new_rows = get_data(conv_result)\n",
    "        with shared_rows.get_lock():\n",
    "            shared_rows.extend(new_rows)\n",
    "        return True, f\"Успешно обработан файл: {file_name}\"\n",
    "    except Exception as e:\n",
    "        return False, f\"Ошибка при обработке файла {file_name}: {str(e)}\"\n",
    "\n",
    "def proccessDocs(dir, num_processes=None):\n",
    "    if num_processes is None:\n",
    "        num_processes = os.cpu_count() - 1\n",
    "    \n",
    "    # Получаем список всех файлов\n",
    "    files = [(os.path.join(dir, file), file.split('.')[0]) \n",
    "             for file in os.listdir(dir)]\n",
    "    total_files = len(files)\n",
    "    \n",
    "    # Создаем общий список и счетчик для прогресса\n",
    "    with Manager() as manager:\n",
    "        shared_rows = manager.list()\n",
    "        \n",
    "        # Создаем частичную функцию с общим списком\n",
    "        process_func = partial(proccessDoc, shared_rows)\n",
    "        \n",
    "        # Инициализируем счетчики для статистики\n",
    "        success_count = 0\n",
    "        error_count = 0\n",
    "        \n",
    "        print(f\"\\nНачало обработки {total_files} файлов используя {num_processes} процессов\")\n",
    "        \n",
    "        # Запускаем пул процессов с прогресс-баром\n",
    "        with Pool(processes=num_processes) as pool:\n",
    "            with tqdm(total=total_files, desc=\"Обработка файлов\", \n",
    "                     unit=\"файл\", ncols=100) as pbar:\n",
    "                \n",
    "                # Используем imap для возможности обновления прогресс-бара\n",
    "                for success, message in pool.imap_unordered(process_func, files):\n",
    "                    if success:\n",
    "                        success_count += 1\n",
    "                    else:\n",
    "                        error_count += 1\n",
    "                        print(f\"\\n{message}\")\n",
    "                    pbar.update()\n",
    "        \n",
    "        # Преобразуем shared_rows обратно в обычный список\n",
    "        global rows\n",
    "        rows = list(shared_rows)\n",
    "        \n",
    "        # Выводим итоговую статистику\n",
    "        print(\"\\nИтоги обработки:\")\n",
    "        print(f\"✓ Успешно обработано: {success_count} файлов\")\n",
    "        if error_count > 0:\n",
    "            print(f\"✗ Ошибок обработки: {error_count} файлов\")\n",
    "        print(f\"Всего извлечено строк: {len(rows)}\")"
   ]
  },
  {
   "cell_type": "code",
   "execution_count": 3,
   "id": "ec0717ce-3dc9-4d31-a1e9-1b6dddfe7079",
   "metadata": {},
   "outputs": [],
   "source": [
    "def convert_doc(input_doc_path: str) -> list:\n",
    "    conv_result = doc_converter.convert(input_doc_path)\n",
    "    new_rows = get_data(conv_result)\n",
    "\n",
    "    return new_rows"
   ]
  },
  {
   "cell_type": "code",
   "execution_count": 4,
   "id": "3e7f1692-63c2-4501-bbe7-3871bcd9a9f1",
   "metadata": {},
   "outputs": [],
   "source": [
    "import os\n",
    "_dir = 'input'\n",
    "\n",
    "files = [(os.path.join(_dir, file)) for file in os.listdir(_dir)]"
   ]
  },
  {
   "cell_type": "code",
   "execution_count": 6,
   "id": "4bed64de-d50c-45aa-96f8-1051c4f8ccca",
   "metadata": {},
   "outputs": [
    {
     "name": "stderr",
     "output_type": "stream",
     "text": [
      "Обработка файлов:  24%|███████████████                                               | 17/70 [17:51<1:05:20, 73.97s/it]"
     ]
    },
    {
     "name": "stdout",
     "output_type": "stream",
     "text": [
      "\u001b[91m*ERR* --- *ERR*\u001b[0m\n",
      "\u001b[91m*ERR* Table is not square! *ERR*\u001b[0m\n",
      "\u001b[93m*Padding to square...*\u001b[0m\n",
      "\u001b[91m*ERR* --- *ERR*\u001b[0m\n",
      "\u001b[91m*ERR* Table is not square! *ERR*\u001b[0m\n",
      "\u001b[93m*Padding to square...*\u001b[0m\n"
     ]
    },
    {
     "name": "stderr",
     "output_type": "stream",
     "text": [
      "Обработка файлов:  34%|████████████████████▏                                      | 24/70 [1:37:24<3:22:26, 264.06s/it]"
     ]
    },
    {
     "name": "stdout",
     "output_type": "stream",
     "text": [
      "\u001b[91m*ERR* --- *ERR*\u001b[0m\n",
      "\u001b[91m*ERR* Table is not square! *ERR*\u001b[0m\n",
      "\u001b[93m*Padding to square...*\u001b[0m\n",
      "\u001b[91m*ERR* --- *ERR*\u001b[0m\n",
      "\u001b[91m*ERR* Table is not square! *ERR*\u001b[0m\n",
      "\u001b[93m*Padding to square...*\u001b[0m\n"
     ]
    },
    {
     "name": "stderr",
     "output_type": "stream",
     "text": [
      "Обработка файлов:  47%|█████████████████████████████▏                                | 33/70 [1:42:30<22:49, 37.02s/it]Encountered an error during conversion of document 62fd8b2fb60a5693c23aab39c30f0cb769e155912b0ffa90e4d0563d949e7361:\n",
      "Traceback (most recent call last):\n",
      "\n",
      "  File \"C:\\Users\\wurfil\\AppData\\Local\\Programs\\Python\\Python311\\Lib\\site-packages\\docling\\pipeline\\base_pipeline.py\", line 149, in _build_document\n",
      "    for p in pipeline_pages:  # Must exhaust!\n",
      "\n",
      "  File \"C:\\Users\\wurfil\\AppData\\Local\\Programs\\Python\\Python311\\Lib\\site-packages\\docling\\pipeline\\base_pipeline.py\", line 116, in _apply_on_pages\n",
      "    yield from page_batch\n",
      "\n",
      "  File \"C:\\Users\\wurfil\\AppData\\Local\\Programs\\Python\\Python311\\Lib\\site-packages\\docling\\models\\page_assemble_model.py\", line 59, in __call__\n",
      "    for page in page_batch:\n",
      "\n",
      "  File \"C:\\Users\\wurfil\\AppData\\Local\\Programs\\Python\\Python311\\Lib\\site-packages\\docling\\models\\table_structure_model.py\", line 166, in __call__\n",
      "    text_piece = page._backend.get_text_in_rect(\n",
      "                 ^^^^^^^^^^^^^^^^^^^^^^^^^^^^^^^\n",
      "\n",
      "  File \"C:\\Users\\wurfil\\AppData\\Local\\Programs\\Python\\Python311\\Lib\\site-packages\\docling\\backend\\docling_parse_backend.py\", line 62, in get_text_in_rect\n",
      "    overlap_frac = cell_bbox.intersection_area_with(bbox) / cell_bbox.area()\n",
      "                   ~~~~~~~~~~~~~~~~~~~~~~~~~~~~~~~~~~~~~~~^~~~~~~~~~~~~~~~~~\n",
      "\n",
      "ZeroDivisionError: float division by zero\n",
      "\n",
      "Обработка файлов:  49%|██████████████████████████████                                | 34/70 [1:42:42<17:49, 29.70s/it]"
     ]
    },
    {
     "name": "stdout",
     "output_type": "stream",
     "text": [
      "Ошибка при обработке input\\39.pdf: float division by zero\n"
     ]
    },
    {
     "name": "stderr",
     "output_type": "stream",
     "text": [
      "Обработка файлов:  50%|███████████████████████████████                               | 35/70 [1:43:25<19:33, 33.54s/it]"
     ]
    },
    {
     "name": "stdout",
     "output_type": "stream",
     "text": [
      "\u001b[91m*ERR* --- *ERR*\u001b[0m\n",
      "\u001b[91m*ERR* Table is not square! *ERR*\u001b[0m\n",
      "\u001b[93m*Padding to square...*\u001b[0m\n"
     ]
    },
    {
     "name": "stderr",
     "output_type": "stream",
     "text": [
      "Обработка файлов:  54%|█████████████████████████████████▋                            | 38/70 [1:50:19<42:46, 80.20s/it]"
     ]
    },
    {
     "name": "stdout",
     "output_type": "stream",
     "text": [
      "\u001b[91m*ERR* --- *ERR*\u001b[0m\n",
      "\u001b[91m*ERR* Table is not square! *ERR*\u001b[0m\n",
      "\u001b[93m*Padding to square...*\u001b[0m\n"
     ]
    },
    {
     "name": "stderr",
     "output_type": "stream",
     "text": [
      "Обработка файлов:  56%|██████████████████████████████████▌                           | 39/70 [1:51:05<36:10, 70.01s/it]Encountered an error during conversion of document e291b305b4cbf12dbe79b51429c1abf848e641f515dffbb32b8769eff2b7860c:\n",
      "Traceback (most recent call last):\n",
      "\n",
      "  File \"C:\\Users\\wurfil\\AppData\\Local\\Programs\\Python\\Python311\\Lib\\site-packages\\docling\\pipeline\\base_pipeline.py\", line 149, in _build_document\n",
      "    for p in pipeline_pages:  # Must exhaust!\n",
      "\n",
      "  File \"C:\\Users\\wurfil\\AppData\\Local\\Programs\\Python\\Python311\\Lib\\site-packages\\docling\\pipeline\\base_pipeline.py\", line 116, in _apply_on_pages\n",
      "    yield from page_batch\n",
      "\n",
      "  File \"C:\\Users\\wurfil\\AppData\\Local\\Programs\\Python\\Python311\\Lib\\site-packages\\docling\\models\\page_assemble_model.py\", line 59, in __call__\n",
      "    for page in page_batch:\n",
      "\n",
      "  File \"C:\\Users\\wurfil\\AppData\\Local\\Programs\\Python\\Python311\\Lib\\site-packages\\docling\\models\\table_structure_model.py\", line 166, in __call__\n",
      "    text_piece = page._backend.get_text_in_rect(\n",
      "                 ^^^^^^^^^^^^^^^^^^^^^^^^^^^^^^^\n",
      "\n",
      "  File \"C:\\Users\\wurfil\\AppData\\Local\\Programs\\Python\\Python311\\Lib\\site-packages\\docling\\backend\\docling_parse_backend.py\", line 62, in get_text_in_rect\n",
      "    overlap_frac = cell_bbox.intersection_area_with(bbox) / cell_bbox.area()\n",
      "                   ~~~~~~~~~~~~~~~~~~~~~~~~~~~~~~~~~~~~~~~^~~~~~~~~~~~~~~~~~\n",
      "\n",
      "ZeroDivisionError: float division by zero\n",
      "\n",
      "Обработка файлов:  57%|███████████████████████████████████▍                          | 40/70 [1:51:56<32:14, 64.47s/it]"
     ]
    },
    {
     "name": "stdout",
     "output_type": "stream",
     "text": [
      "Ошибка при обработке input\\44.pdf: float division by zero\n"
     ]
    },
    {
     "name": "stderr",
     "output_type": "stream",
     "text": [
      "Обработка файлов:  80%|████████████████████████████████████████████████▊            | 56/70 [3:33:09<58:49, 252.07s/it]"
     ]
    },
    {
     "name": "stdout",
     "output_type": "stream",
     "text": [
      "\u001b[91m*ERR* --- *ERR*\u001b[0m\n",
      "\u001b[91m*ERR* Table is not square! *ERR*\u001b[0m\n",
      "\u001b[93m*Padding to square...*\u001b[0m\n",
      "\u001b[91m*ERR* --- *ERR*\u001b[0m\n",
      "\u001b[91m*ERR* Table is not square! *ERR*\u001b[0m\n",
      "\u001b[93m*Padding to square...*\u001b[0m\n"
     ]
    },
    {
     "name": "stderr",
     "output_type": "stream",
     "text": [
      "Обработка файлов:  87%|█████████████████████████████████████████████████████▏       | 61/70 [3:44:02<15:02, 100.33s/it]Encountered an error during conversion of document 61d2f566e0e6a25594b13f8727761b5b458e74300bd94f0599550519df7a3a08:\n",
      "Traceback (most recent call last):\n",
      "\n",
      "  File \"C:\\Users\\wurfil\\AppData\\Local\\Programs\\Python\\Python311\\Lib\\site-packages\\docling\\pipeline\\base_pipeline.py\", line 149, in _build_document\n",
      "    for p in pipeline_pages:  # Must exhaust!\n",
      "\n",
      "  File \"C:\\Users\\wurfil\\AppData\\Local\\Programs\\Python\\Python311\\Lib\\site-packages\\docling\\pipeline\\base_pipeline.py\", line 116, in _apply_on_pages\n",
      "    yield from page_batch\n",
      "\n",
      "  File \"C:\\Users\\wurfil\\AppData\\Local\\Programs\\Python\\Python311\\Lib\\site-packages\\docling\\models\\page_assemble_model.py\", line 59, in __call__\n",
      "    for page in page_batch:\n",
      "\n",
      "  File \"C:\\Users\\wurfil\\AppData\\Local\\Programs\\Python\\Python311\\Lib\\site-packages\\docling\\models\\table_structure_model.py\", line 166, in __call__\n",
      "    text_piece = page._backend.get_text_in_rect(\n",
      "                 ^^^^^^^^^^^^^^^^^^^^^^^^^^^^^^^\n",
      "\n",
      "  File \"C:\\Users\\wurfil\\AppData\\Local\\Programs\\Python\\Python311\\Lib\\site-packages\\docling\\backend\\docling_parse_backend.py\", line 62, in get_text_in_rect\n",
      "    overlap_frac = cell_bbox.intersection_area_with(bbox) / cell_bbox.area()\n",
      "                   ~~~~~~~~~~~~~~~~~~~~~~~~~~~~~~~~~~~~~~~^~~~~~~~~~~~~~~~~~\n",
      "\n",
      "ZeroDivisionError: float division by zero\n",
      "\n",
      "Обработка файлов:  89%|██████████████████████████████████████████████████████▉       | 62/70 [3:44:09<09:38, 72.34s/it]"
     ]
    },
    {
     "name": "stdout",
     "output_type": "stream",
     "text": [
      "Ошибка при обработке input\\64.pdf: float division by zero\n"
     ]
    },
    {
     "name": "stderr",
     "output_type": "stream",
     "text": [
      "Encountered an error during conversion of document d78ada7eb0aa81c08a3e691c3b4078df94a65312e4cebb4f428d38f54c250d02:\n",
      "Traceback (most recent call last):\n",
      "\n",
      "  File \"C:\\Users\\wurfil\\AppData\\Local\\Programs\\Python\\Python311\\Lib\\site-packages\\docling\\pipeline\\base_pipeline.py\", line 149, in _build_document\n",
      "    for p in pipeline_pages:  # Must exhaust!\n",
      "\n",
      "  File \"C:\\Users\\wurfil\\AppData\\Local\\Programs\\Python\\Python311\\Lib\\site-packages\\docling\\pipeline\\base_pipeline.py\", line 116, in _apply_on_pages\n",
      "    yield from page_batch\n",
      "\n",
      "  File \"C:\\Users\\wurfil\\AppData\\Local\\Programs\\Python\\Python311\\Lib\\site-packages\\docling\\models\\page_assemble_model.py\", line 59, in __call__\n",
      "    for page in page_batch:\n",
      "\n",
      "  File \"C:\\Users\\wurfil\\AppData\\Local\\Programs\\Python\\Python311\\Lib\\site-packages\\docling\\models\\table_structure_model.py\", line 166, in __call__\n",
      "    text_piece = page._backend.get_text_in_rect(\n",
      "                 ^^^^^^^^^^^^^^^^^^^^^^^^^^^^^^^\n",
      "\n",
      "  File \"C:\\Users\\wurfil\\AppData\\Local\\Programs\\Python\\Python311\\Lib\\site-packages\\docling\\backend\\docling_parse_backend.py\", line 62, in get_text_in_rect\n",
      "    overlap_frac = cell_bbox.intersection_area_with(bbox) / cell_bbox.area()\n",
      "                   ~~~~~~~~~~~~~~~~~~~~~~~~~~~~~~~~~~~~~~~^~~~~~~~~~~~~~~~~~\n",
      "\n",
      "ZeroDivisionError: float division by zero\n",
      "\n",
      "Обработка файлов:  90%|███████████████████████████████████████████████████████▊      | 63/70 [3:45:07<07:55, 67.92s/it]"
     ]
    },
    {
     "name": "stdout",
     "output_type": "stream",
     "text": [
      "Ошибка при обработке input\\65.pdf: float division by zero\n"
     ]
    },
    {
     "name": "stderr",
     "output_type": "stream",
     "text": [
      "Обработка файлов: 100%|█████████████████████████████████████████████████████████████| 70/70 [3:59:01<00:00, 204.87s/it]"
     ]
    },
    {
     "name": "stdout",
     "output_type": "stream",
     "text": [
      "\n",
      "Обработка завершена:\n",
      "Успешно: 66\n",
      "С ошибками: 4\n",
      "Всего извлечено строк: 4452\n"
     ]
    },
    {
     "name": "stderr",
     "output_type": "stream",
     "text": [
      "\n"
     ]
    }
   ],
   "source": [
    "from tqdm import tqdm\n",
    "\n",
    "def process_documents(files):\n",
    "    converted_docs = []\n",
    "    successful = 0\n",
    "    failed = 0\n",
    "    \n",
    "    for file in tqdm(files, desc=\"Обработка файлов\"):\n",
    "        try:\n",
    "            result = convert_doc(file)\n",
    "            if result:\n",
    "                converted_docs.extend(result)\n",
    "                successful += 1\n",
    "            else:\n",
    "                failed += 1\n",
    "        except Exception as e:\n",
    "            failed += 1\n",
    "            print(f\"Ошибка при обработке {file}: {str(e)}\")\n",
    "    \n",
    "    print(f\"\\nОбработка завершена:\")\n",
    "    print(f\"Успешно: {successful}\")\n",
    "    print(f\"С ошибками: {failed}\")\n",
    "    print(f\"Всего извлечено строк: {len(converted_docs)}\")\n",
    "    \n",
    "    return converted_docs\n",
    "converted_docs = process_documents(files)"
   ]
  },
  {
   "cell_type": "code",
   "execution_count": 31,
   "id": "b0e22265-eba7-45bc-840e-44c4327e7dae",
   "metadata": {},
   "outputs": [
    {
     "name": "stderr",
     "output_type": "stream",
     "text": [
      "ERROR:docling.datamodel.document:An unexpected error occurred while opening the document 0.pdf\n",
      "Traceback (most recent call last):\n",
      "  File \"C:\\Users\\wurfil\\AppData\\Local\\Programs\\Python\\Python311\\Lib\\site-packages\\docling\\datamodel\\document.py\", line 120, in __init__\n",
      "    self._init_doc(backend, path_or_stream)\n",
      "  File \"C:\\Users\\wurfil\\AppData\\Local\\Programs\\Python\\Python311\\Lib\\site-packages\\docling\\datamodel\\document.py\", line 173, in _init_doc\n",
      "    self._backend = backend(self, path_or_stream=path_or_stream)\n",
      "                    ^^^^^^^^^^^^^^^^^^^^^^^^^^^^^^^^^^^^^^^^^^^^\n",
      "  File \"C:\\Users\\wurfil\\AppData\\Local\\Programs\\Python\\Python311\\Lib\\site-packages\\docling\\backend\\docling_parse_backend.py\", line 194, in __init__\n",
      "    self._pdoc = pdfium.PdfDocument(self.path_or_stream)\n",
      "                 ^^^^^^^^^^^^^^^^^^^^^^^^^^^^^^^^^^^^^^^\n",
      "  File \"C:\\Users\\wurfil\\AppData\\Local\\Programs\\Python\\Python311\\Lib\\site-packages\\pypdfium2\\_helpers\\document.py\", line 78, in __init__\n",
      "    self.raw, to_hold, to_close = _open_pdf(self._input, self._password, self._autoclose)\n",
      "                                  ^^^^^^^^^^^^^^^^^^^^^^^^^^^^^^^^^^^^^^^^^^^^^^^^^^^^^^^\n",
      "  File \"C:\\Users\\wurfil\\AppData\\Local\\Programs\\Python\\Python311\\Lib\\site-packages\\pypdfium2\\_helpers\\document.py\", line 678, in _open_pdf\n",
      "    raise PdfiumError(f\"Failed to load document (PDFium: {pdfium_i.ErrorToStr.get(err_code)}).\")\n",
      "pypdfium2._helpers.misc.PdfiumError: Failed to load document (PDFium: Data format error).\n",
      "ERROR:root:Ошибка при обработке .\\input\\0.pdf: Input document input\\0.pdf is not valid.\n",
      "ERROR:docling.datamodel.document:An unexpected error occurred while opening the document 1.pdf\n",
      "Traceback (most recent call last):\n",
      "  File \"C:\\Users\\wurfil\\AppData\\Local\\Programs\\Python\\Python311\\Lib\\site-packages\\docling\\datamodel\\document.py\", line 120, in __init__\n",
      "    self._init_doc(backend, path_or_stream)\n",
      "  File \"C:\\Users\\wurfil\\AppData\\Local\\Programs\\Python\\Python311\\Lib\\site-packages\\docling\\datamodel\\document.py\", line 173, in _init_doc\n",
      "    self._backend = backend(self, path_or_stream=path_or_stream)\n",
      "                    ^^^^^^^^^^^^^^^^^^^^^^^^^^^^^^^^^^^^^^^^^^^^\n",
      "  File \"C:\\Users\\wurfil\\AppData\\Local\\Programs\\Python\\Python311\\Lib\\site-packages\\docling\\backend\\docling_parse_backend.py\", line 194, in __init__\n",
      "    self._pdoc = pdfium.PdfDocument(self.path_or_stream)\n",
      "                 ^^^^^^^^^^^^^^^^^^^^^^^^^^^^^^^^^^^^^^^\n",
      "  File \"C:\\Users\\wurfil\\AppData\\Local\\Programs\\Python\\Python311\\Lib\\site-packages\\pypdfium2\\_helpers\\document.py\", line 78, in __init__\n",
      "    self.raw, to_hold, to_close = _open_pdf(self._input, self._password, self._autoclose)\n",
      "                                  ^^^^^^^^^^^^^^^^^^^^^^^^^^^^^^^^^^^^^^^^^^^^^^^^^^^^^^^\n",
      "  File \"C:\\Users\\wurfil\\AppData\\Local\\Programs\\Python\\Python311\\Lib\\site-packages\\pypdfium2\\_helpers\\document.py\", line 678, in _open_pdf\n",
      "    raise PdfiumError(f\"Failed to load document (PDFium: {pdfium_i.ErrorToStr.get(err_code)}).\")\n",
      "pypdfium2._helpers.misc.PdfiumError: Failed to load document (PDFium: Data format error).\n",
      "ERROR:root:Ошибка при обработке .\\input\\1.pdf: Input document input\\1.pdf is not valid.\n",
      "ERROR:docling.datamodel.document:An unexpected error occurred while opening the document 14.pdf\n",
      "Traceback (most recent call last):\n",
      "  File \"C:\\Users\\wurfil\\AppData\\Local\\Programs\\Python\\Python311\\Lib\\site-packages\\docling\\datamodel\\document.py\", line 120, in __init__\n",
      "    self._init_doc(backend, path_or_stream)\n",
      "  File \"C:\\Users\\wurfil\\AppData\\Local\\Programs\\Python\\Python311\\Lib\\site-packages\\docling\\datamodel\\document.py\", line 173, in _init_doc\n",
      "    self._backend = backend(self, path_or_stream=path_or_stream)\n",
      "                    ^^^^^^^^^^^^^^^^^^^^^^^^^^^^^^^^^^^^^^^^^^^^\n",
      "  File \"C:\\Users\\wurfil\\AppData\\Local\\Programs\\Python\\Python311\\Lib\\site-packages\\docling\\backend\\docling_parse_backend.py\", line 194, in __init__\n",
      "    self._pdoc = pdfium.PdfDocument(self.path_or_stream)\n",
      "                 ^^^^^^^^^^^^^^^^^^^^^^^^^^^^^^^^^^^^^^^\n",
      "  File \"C:\\Users\\wurfil\\AppData\\Local\\Programs\\Python\\Python311\\Lib\\site-packages\\pypdfium2\\_helpers\\document.py\", line 78, in __init__\n",
      "    self.raw, to_hold, to_close = _open_pdf(self._input, self._password, self._autoclose)\n",
      "                                  ^^^^^^^^^^^^^^^^^^^^^^^^^^^^^^^^^^^^^^^^^^^^^^^^^^^^^^^\n",
      "  File \"C:\\Users\\wurfil\\AppData\\Local\\Programs\\Python\\Python311\\Lib\\site-packages\\pypdfium2\\_helpers\\document.py\", line 678, in _open_pdf\n",
      "    raise PdfiumError(f\"Failed to load document (PDFium: {pdfium_i.ErrorToStr.get(err_code)}).\")\n",
      "pypdfium2._helpers.misc.PdfiumError: Failed to load document (PDFium: Data format error).\n",
      "ERROR:root:Ошибка при обработке .\\input\\14.pdf: Input document input\\14.pdf is not valid.\n",
      "ERROR:docling.datamodel.document:An unexpected error occurred while opening the document 13.pdf\n",
      "Traceback (most recent call last):\n",
      "  File \"C:\\Users\\wurfil\\AppData\\Local\\Programs\\Python\\Python311\\Lib\\site-packages\\docling\\datamodel\\document.py\", line 120, in __init__\n",
      "    self._init_doc(backend, path_or_stream)\n",
      "  File \"C:\\Users\\wurfil\\AppData\\Local\\Programs\\Python\\Python311\\Lib\\site-packages\\docling\\datamodel\\document.py\", line 173, in _init_doc\n",
      "    self._backend = backend(self, path_or_stream=path_or_stream)\n",
      "                    ^^^^^^^^^^^^^^^^^^^^^^^^^^^^^^^^^^^^^^^^^^^^\n",
      "  File \"C:\\Users\\wurfil\\AppData\\Local\\Programs\\Python\\Python311\\Lib\\site-packages\\docling\\backend\\docling_parse_backend.py\", line 194, in __init__\n",
      "    self._pdoc = pdfium.PdfDocument(self.path_or_stream)\n",
      "                 ^^^^^^^^^^^^^^^^^^^^^^^^^^^^^^^^^^^^^^^\n",
      "  File \"C:\\Users\\wurfil\\AppData\\Local\\Programs\\Python\\Python311\\Lib\\site-packages\\pypdfium2\\_helpers\\document.py\", line 78, in __init__\n",
      "    self.raw, to_hold, to_close = _open_pdf(self._input, self._password, self._autoclose)\n",
      "                                  ^^^^^^^^^^^^^^^^^^^^^^^^^^^^^^^^^^^^^^^^^^^^^^^^^^^^^^^\n",
      "  File \"C:\\Users\\wurfil\\AppData\\Local\\Programs\\Python\\Python311\\Lib\\site-packages\\pypdfium2\\_helpers\\document.py\", line 678, in _open_pdf\n",
      "    raise PdfiumError(f\"Failed to load document (PDFium: {pdfium_i.ErrorToStr.get(err_code)}).\")\n",
      "pypdfium2._helpers.misc.PdfiumError: Failed to load document (PDFium: Data format error).\n",
      "ERROR:root:Ошибка при обработке .\\input\\13.pdf: Input document input\\13.pdf is not valid.\n",
      "ERROR:docling.datamodel.document:An unexpected error occurred while opening the document 12.pdf\n",
      "Traceback (most recent call last):\n",
      "  File \"C:\\Users\\wurfil\\AppData\\Local\\Programs\\Python\\Python311\\Lib\\site-packages\\docling\\datamodel\\document.py\", line 120, in __init__\n",
      "    self._init_doc(backend, path_or_stream)\n",
      "  File \"C:\\Users\\wurfil\\AppData\\Local\\Programs\\Python\\Python311\\Lib\\site-packages\\docling\\datamodel\\document.py\", line 173, in _init_doc\n",
      "    self._backend = backend(self, path_or_stream=path_or_stream)\n",
      "                    ^^^^^^^^^^^^^^^^^^^^^^^^^^^^^^^^^^^^^^^^^^^^\n",
      "  File \"C:\\Users\\wurfil\\AppData\\Local\\Programs\\Python\\Python311\\Lib\\site-packages\\docling\\backend\\docling_parse_backend.py\", line 194, in __init__\n",
      "    self._pdoc = pdfium.PdfDocument(self.path_or_stream)\n",
      "                 ^^^^^^^^^^^^^^^^^^^^^^^^^^^^^^^^^^^^^^^\n",
      "  File \"C:\\Users\\wurfil\\AppData\\Local\\Programs\\Python\\Python311\\Lib\\site-packages\\pypdfium2\\_helpers\\document.py\", line 78, in __init__\n",
      "    self.raw, to_hold, to_close = _open_pdf(self._input, self._password, self._autoclose)\n",
      "                                  ^^^^^^^^^^^^^^^^^^^^^^^^^^^^^^^^^^^^^^^^^^^^^^^^^^^^^^^\n",
      "  File \"C:\\Users\\wurfil\\AppData\\Local\\Programs\\Python\\Python311\\Lib\\site-packages\\pypdfium2\\_helpers\\document.py\", line 678, in _open_pdf\n",
      "    raise PdfiumError(f\"Failed to load document (PDFium: {pdfium_i.ErrorToStr.get(err_code)}).\")\n",
      "pypdfium2._helpers.misc.PdfiumError: Failed to load document (PDFium: Data format error).\n",
      "ERROR:root:Ошибка при обработке .\\input\\12.pdf: Input document input\\12.pdf is not valid.\n",
      "ERROR:docling.datamodel.document:An unexpected error occurred while opening the document 17.pdf\n",
      "Traceback (most recent call last):\n",
      "  File \"C:\\Users\\wurfil\\AppData\\Local\\Programs\\Python\\Python311\\Lib\\site-packages\\docling\\datamodel\\document.py\", line 120, in __init__\n",
      "    self._init_doc(backend, path_or_stream)\n",
      "  File \"C:\\Users\\wurfil\\AppData\\Local\\Programs\\Python\\Python311\\Lib\\site-packages\\docling\\datamodel\\document.py\", line 173, in _init_doc\n",
      "    self._backend = backend(self, path_or_stream=path_or_stream)\n",
      "                    ^^^^^^^^^^^^^^^^^^^^^^^^^^^^^^^^^^^^^^^^^^^^\n",
      "  File \"C:\\Users\\wurfil\\AppData\\Local\\Programs\\Python\\Python311\\Lib\\site-packages\\docling\\backend\\docling_parse_backend.py\", line 194, in __init__\n",
      "    self._pdoc = pdfium.PdfDocument(self.path_or_stream)\n",
      "                 ^^^^^^^^^^^^^^^^^^^^^^^^^^^^^^^^^^^^^^^\n",
      "  File \"C:\\Users\\wurfil\\AppData\\Local\\Programs\\Python\\Python311\\Lib\\site-packages\\pypdfium2\\_helpers\\document.py\", line 78, in __init__\n",
      "    self.raw, to_hold, to_close = _open_pdf(self._input, self._password, self._autoclose)\n",
      "                                  ^^^^^^^^^^^^^^^^^^^^^^^^^^^^^^^^^^^^^^^^^^^^^^^^^^^^^^^\n",
      "  File \"C:\\Users\\wurfil\\AppData\\Local\\Programs\\Python\\Python311\\Lib\\site-packages\\pypdfium2\\_helpers\\document.py\", line 678, in _open_pdf\n",
      "    raise PdfiumError(f\"Failed to load document (PDFium: {pdfium_i.ErrorToStr.get(err_code)}).\")\n",
      "pypdfium2._helpers.misc.PdfiumError: Failed to load document (PDFium: Data format error).\n",
      "ERROR:root:Ошибка при обработке .\\input\\17.pdf: Input document input\\17.pdf is not valid.\n",
      "ERROR:docling.datamodel.document:An unexpected error occurred while opening the document 18.pdf\n",
      "Traceback (most recent call last):\n",
      "  File \"C:\\Users\\wurfil\\AppData\\Local\\Programs\\Python\\Python311\\Lib\\site-packages\\docling\\datamodel\\document.py\", line 120, in __init__\n",
      "    self._init_doc(backend, path_or_stream)\n",
      "  File \"C:\\Users\\wurfil\\AppData\\Local\\Programs\\Python\\Python311\\Lib\\site-packages\\docling\\datamodel\\document.py\", line 173, in _init_doc\n",
      "    self._backend = backend(self, path_or_stream=path_or_stream)\n",
      "                    ^^^^^^^^^^^^^^^^^^^^^^^^^^^^^^^^^^^^^^^^^^^^\n",
      "  File \"C:\\Users\\wurfil\\AppData\\Local\\Programs\\Python\\Python311\\Lib\\site-packages\\docling\\backend\\docling_parse_backend.py\", line 194, in __init__\n",
      "    self._pdoc = pdfium.PdfDocument(self.path_or_stream)\n",
      "                 ^^^^^^^^^^^^^^^^^^^^^^^^^^^^^^^^^^^^^^^\n",
      "  File \"C:\\Users\\wurfil\\AppData\\Local\\Programs\\Python\\Python311\\Lib\\site-packages\\pypdfium2\\_helpers\\document.py\", line 78, in __init__\n",
      "    self.raw, to_hold, to_close = _open_pdf(self._input, self._password, self._autoclose)\n",
      "                                  ^^^^^^^^^^^^^^^^^^^^^^^^^^^^^^^^^^^^^^^^^^^^^^^^^^^^^^^\n",
      "  File \"C:\\Users\\wurfil\\AppData\\Local\\Programs\\Python\\Python311\\Lib\\site-packages\\pypdfium2\\_helpers\\document.py\", line 678, in _open_pdf\n",
      "    raise PdfiumError(f\"Failed to load document (PDFium: {pdfium_i.ErrorToStr.get(err_code)}).\")\n",
      "pypdfium2._helpers.misc.PdfiumError: Failed to load document (PDFium: Data format error).\n",
      "ERROR:root:Ошибка при обработке .\\input\\18.pdf: Input document input\\18.pdf is not valid.\n",
      "ERROR:docling.datamodel.document:An unexpected error occurred while opening the document 19.pdf\n",
      "Traceback (most recent call last):\n",
      "  File \"C:\\Users\\wurfil\\AppData\\Local\\Programs\\Python\\Python311\\Lib\\site-packages\\docling\\datamodel\\document.py\", line 120, in __init__\n",
      "    self._init_doc(backend, path_or_stream)\n",
      "  File \"C:\\Users\\wurfil\\AppData\\Local\\Programs\\Python\\Python311\\Lib\\site-packages\\docling\\datamodel\\document.py\", line 173, in _init_doc\n",
      "    self._backend = backend(self, path_or_stream=path_or_stream)\n",
      "                    ^^^^^^^^^^^^^^^^^^^^^^^^^^^^^^^^^^^^^^^^^^^^\n",
      "  File \"C:\\Users\\wurfil\\AppData\\Local\\Programs\\Python\\Python311\\Lib\\site-packages\\docling\\backend\\docling_parse_backend.py\", line 194, in __init__\n",
      "    self._pdoc = pdfium.PdfDocument(self.path_or_stream)\n",
      "                 ^^^^^^^^^^^^^^^^^^^^^^^^^^^^^^^^^^^^^^^\n",
      "  File \"C:\\Users\\wurfil\\AppData\\Local\\Programs\\Python\\Python311\\Lib\\site-packages\\pypdfium2\\_helpers\\document.py\", line 78, in __init__\n",
      "    self.raw, to_hold, to_close = _open_pdf(self._input, self._password, self._autoclose)\n",
      "                                  ^^^^^^^^^^^^^^^^^^^^^^^^^^^^^^^^^^^^^^^^^^^^^^^^^^^^^^^\n",
      "  File \"C:\\Users\\wurfil\\AppData\\Local\\Programs\\Python\\Python311\\Lib\\site-packages\\pypdfium2\\_helpers\\document.py\", line 678, in _open_pdf\n",
      "    raise PdfiumError(f\"Failed to load document (PDFium: {pdfium_i.ErrorToStr.get(err_code)}).\")\n",
      "pypdfium2._helpers.misc.PdfiumError: Failed to load document (PDFium: Data format error).\n",
      "ERROR:root:Ошибка при обработке .\\input\\19.pdf: Input document input\\19.pdf is not valid.\n",
      "ERROR:docling.datamodel.document:An unexpected error occurred while opening the document 16.pdf\n",
      "Traceback (most recent call last):\n",
      "  File \"C:\\Users\\wurfil\\AppData\\Local\\Programs\\Python\\Python311\\Lib\\site-packages\\docling\\datamodel\\document.py\", line 120, in __init__\n",
      "    self._init_doc(backend, path_or_stream)\n",
      "  File \"C:\\Users\\wurfil\\AppData\\Local\\Programs\\Python\\Python311\\Lib\\site-packages\\docling\\datamodel\\document.py\", line 173, in _init_doc\n",
      "    self._backend = backend(self, path_or_stream=path_or_stream)\n",
      "                    ^^^^^^^^^^^^^^^^^^^^^^^^^^^^^^^^^^^^^^^^^^^^\n",
      "  File \"C:\\Users\\wurfil\\AppData\\Local\\Programs\\Python\\Python311\\Lib\\site-packages\\docling\\backend\\docling_parse_backend.py\", line 194, in __init__\n",
      "    self._pdoc = pdfium.PdfDocument(self.path_or_stream)\n",
      "                 ^^^^^^^^^^^^^^^^^^^^^^^^^^^^^^^^^^^^^^^\n",
      "  File \"C:\\Users\\wurfil\\AppData\\Local\\Programs\\Python\\Python311\\Lib\\site-packages\\pypdfium2\\_helpers\\document.py\", line 78, in __init__\n",
      "    self.raw, to_hold, to_close = _open_pdf(self._input, self._password, self._autoclose)\n",
      "                                  ^^^^^^^^^^^^^^^^^^^^^^^^^^^^^^^^^^^^^^^^^^^^^^^^^^^^^^^\n",
      "  File \"C:\\Users\\wurfil\\AppData\\Local\\Programs\\Python\\Python311\\Lib\\site-packages\\pypdfium2\\_helpers\\document.py\", line 678, in _open_pdf\n",
      "    raise PdfiumError(f\"Failed to load document (PDFium: {pdfium_i.ErrorToStr.get(err_code)}).\")\n",
      "pypdfium2._helpers.misc.PdfiumError: Failed to load document (PDFium: Data format error).\n",
      "ERROR:root:Ошибка при обработке .\\input\\16.pdf: Input document input\\16.pdf is not valid.\n",
      "ERROR:docling.datamodel.document:An unexpected error occurred while opening the document 20.pdf\n",
      "Traceback (most recent call last):\n",
      "  File \"C:\\Users\\wurfil\\AppData\\Local\\Programs\\Python\\Python311\\Lib\\site-packages\\docling\\datamodel\\document.py\", line 120, in __init__\n",
      "    self._init_doc(backend, path_or_stream)\n",
      "  File \"C:\\Users\\wurfil\\AppData\\Local\\Programs\\Python\\Python311\\Lib\\site-packages\\docling\\datamodel\\document.py\", line 173, in _init_doc\n",
      "    self._backend = backend(self, path_or_stream=path_or_stream)\n",
      "                    ^^^^^^^^^^^^^^^^^^^^^^^^^^^^^^^^^^^^^^^^^^^^\n",
      "  File \"C:\\Users\\wurfil\\AppData\\Local\\Programs\\Python\\Python311\\Lib\\site-packages\\docling\\backend\\docling_parse_backend.py\", line 194, in __init__\n",
      "    self._pdoc = pdfium.PdfDocument(self.path_or_stream)\n",
      "                 ^^^^^^^^^^^^^^^^^^^^^^^^^^^^^^^^^^^^^^^\n",
      "  File \"C:\\Users\\wurfil\\AppData\\Local\\Programs\\Python\\Python311\\Lib\\site-packages\\pypdfium2\\_helpers\\document.py\", line 78, in __init__\n",
      "    self.raw, to_hold, to_close = _open_pdf(self._input, self._password, self._autoclose)\n",
      "                                  ^^^^^^^^^^^^^^^^^^^^^^^^^^^^^^^^^^^^^^^^^^^^^^^^^^^^^^^\n",
      "  File \"C:\\Users\\wurfil\\AppData\\Local\\Programs\\Python\\Python311\\Lib\\site-packages\\pypdfium2\\_helpers\\document.py\", line 678, in _open_pdf\n",
      "    raise PdfiumError(f\"Failed to load document (PDFium: {pdfium_i.ErrorToStr.get(err_code)}).\")\n",
      "pypdfium2._helpers.misc.PdfiumError: Failed to load document (PDFium: Data format error).\n",
      "ERROR:root:Ошибка при обработке .\\input\\20.pdf: Input document input\\20.pdf is not valid.\n",
      "ERROR:docling.datamodel.document:An unexpected error occurred while opening the document 15.pdf\n",
      "Traceback (most recent call last):\n",
      "  File \"C:\\Users\\wurfil\\AppData\\Local\\Programs\\Python\\Python311\\Lib\\site-packages\\docling\\datamodel\\document.py\", line 120, in __init__\n",
      "    self._init_doc(backend, path_or_stream)\n",
      "  File \"C:\\Users\\wurfil\\AppData\\Local\\Programs\\Python\\Python311\\Lib\\site-packages\\docling\\datamodel\\document.py\", line 173, in _init_doc\n",
      "    self._backend = backend(self, path_or_stream=path_or_stream)\n",
      "                    ^^^^^^^^^^^^^^^^^^^^^^^^^^^^^^^^^^^^^^^^^^^^\n",
      "  File \"C:\\Users\\wurfil\\AppData\\Local\\Programs\\Python\\Python311\\Lib\\site-packages\\docling\\backend\\docling_parse_backend.py\", line 194, in __init__\n",
      "    self._pdoc = pdfium.PdfDocument(self.path_or_stream)\n",
      "                 ^^^^^^^^^^^^^^^^^^^^^^^^^^^^^^^^^^^^^^^\n",
      "  File \"C:\\Users\\wurfil\\AppData\\Local\\Programs\\Python\\Python311\\Lib\\site-packages\\pypdfium2\\_helpers\\document.py\", line 78, in __init__\n",
      "    self.raw, to_hold, to_close = _open_pdf(self._input, self._password, self._autoclose)\n",
      "                                  ^^^^^^^^^^^^^^^^^^^^^^^^^^^^^^^^^^^^^^^^^^^^^^^^^^^^^^^\n",
      "  File \"C:\\Users\\wurfil\\AppData\\Local\\Programs\\Python\\Python311\\Lib\\site-packages\\pypdfium2\\_helpers\\document.py\", line 678, in _open_pdf\n",
      "    raise PdfiumError(f\"Failed to load document (PDFium: {pdfium_i.ErrorToStr.get(err_code)}).\")\n",
      "pypdfium2._helpers.misc.PdfiumError: Failed to load document (PDFium: Data format error).\n",
      "ERROR:root:Ошибка при обработке .\\input\\15.pdf: Input document input\\15.pdf is not valid.\n",
      "ERROR:docling.datamodel.document:An unexpected error occurred while opening the document 22.pdf\n",
      "Traceback (most recent call last):\n",
      "  File \"C:\\Users\\wurfil\\AppData\\Local\\Programs\\Python\\Python311\\Lib\\site-packages\\docling\\datamodel\\document.py\", line 120, in __init__\n",
      "    self._init_doc(backend, path_or_stream)\n",
      "  File \"C:\\Users\\wurfil\\AppData\\Local\\Programs\\Python\\Python311\\Lib\\site-packages\\docling\\datamodel\\document.py\", line 173, in _init_doc\n",
      "    self._backend = backend(self, path_or_stream=path_or_stream)\n",
      "                    ^^^^^^^^^^^^^^^^^^^^^^^^^^^^^^^^^^^^^^^^^^^^\n",
      "  File \"C:\\Users\\wurfil\\AppData\\Local\\Programs\\Python\\Python311\\Lib\\site-packages\\docling\\backend\\docling_parse_backend.py\", line 194, in __init__\n",
      "    self._pdoc = pdfium.PdfDocument(self.path_or_stream)\n",
      "                 ^^^^^^^^^^^^^^^^^^^^^^^^^^^^^^^^^^^^^^^\n",
      "  File \"C:\\Users\\wurfil\\AppData\\Local\\Programs\\Python\\Python311\\Lib\\site-packages\\pypdfium2\\_helpers\\document.py\", line 78, in __init__\n",
      "    self.raw, to_hold, to_close = _open_pdf(self._input, self._password, self._autoclose)\n",
      "                                  ^^^^^^^^^^^^^^^^^^^^^^^^^^^^^^^^^^^^^^^^^^^^^^^^^^^^^^^\n",
      "  File \"C:\\Users\\wurfil\\AppData\\Local\\Programs\\Python\\Python311\\Lib\\site-packages\\pypdfium2\\_helpers\\document.py\", line 678, in _open_pdf\n",
      "    raise PdfiumError(f\"Failed to load document (PDFium: {pdfium_i.ErrorToStr.get(err_code)}).\")\n",
      "pypdfium2._helpers.misc.PdfiumError: Failed to load document (PDFium: Data format error).\n",
      "ERROR:root:Ошибка при обработке .\\input\\22.pdf: Input document input\\22.pdf is not valid.\n",
      "ERROR:docling.datamodel.document:An unexpected error occurred while opening the document 21.pdf\n",
      "Traceback (most recent call last):\n",
      "  File \"C:\\Users\\wurfil\\AppData\\Local\\Programs\\Python\\Python311\\Lib\\site-packages\\docling\\datamodel\\document.py\", line 120, in __init__\n",
      "    self._init_doc(backend, path_or_stream)\n",
      "  File \"C:\\Users\\wurfil\\AppData\\Local\\Programs\\Python\\Python311\\Lib\\site-packages\\docling\\datamodel\\document.py\", line 173, in _init_doc\n",
      "    self._backend = backend(self, path_or_stream=path_or_stream)\n",
      "                    ^^^^^^^^^^^^^^^^^^^^^^^^^^^^^^^^^^^^^^^^^^^^\n",
      "  File \"C:\\Users\\wurfil\\AppData\\Local\\Programs\\Python\\Python311\\Lib\\site-packages\\docling\\backend\\docling_parse_backend.py\", line 194, in __init__\n",
      "    self._pdoc = pdfium.PdfDocument(self.path_or_stream)\n",
      "                 ^^^^^^^^^^^^^^^^^^^^^^^^^^^^^^^^^^^^^^^\n",
      "  File \"C:\\Users\\wurfil\\AppData\\Local\\Programs\\Python\\Python311\\Lib\\site-packages\\pypdfium2\\_helpers\\document.py\", line 78, in __init__\n",
      "    self.raw, to_hold, to_close = _open_pdf(self._input, self._password, self._autoclose)\n",
      "                                  ^^^^^^^^^^^^^^^^^^^^^^^^^^^^^^^^^^^^^^^^^^^^^^^^^^^^^^^\n",
      "  File \"C:\\Users\\wurfil\\AppData\\Local\\Programs\\Python\\Python311\\Lib\\site-packages\\pypdfium2\\_helpers\\document.py\", line 678, in _open_pdf\n",
      "    raise PdfiumError(f\"Failed to load document (PDFium: {pdfium_i.ErrorToStr.get(err_code)}).\")\n",
      "pypdfium2._helpers.misc.PdfiumError: Failed to load document (PDFium: Data format error).\n",
      "ERROR:root:Ошибка при обработке .\\input\\21.pdf: Input document input\\21.pdf is not valid.\n",
      "ERROR:docling.datamodel.document:An unexpected error occurred while opening the document 11.pdf\n",
      "Traceback (most recent call last):\n",
      "  File \"C:\\Users\\wurfil\\AppData\\Local\\Programs\\Python\\Python311\\Lib\\site-packages\\docling\\datamodel\\document.py\", line 120, in __init__\n",
      "    self._init_doc(backend, path_or_stream)\n",
      "  File \"C:\\Users\\wurfil\\AppData\\Local\\Programs\\Python\\Python311\\Lib\\site-packages\\docling\\datamodel\\document.py\", line 173, in _init_doc\n",
      "    self._backend = backend(self, path_or_stream=path_or_stream)\n",
      "                    ^^^^^^^^^^^^^^^^^^^^^^^^^^^^^^^^^^^^^^^^^^^^\n",
      "  File \"C:\\Users\\wurfil\\AppData\\Local\\Programs\\Python\\Python311\\Lib\\site-packages\\docling\\backend\\docling_parse_backend.py\", line 194, in __init__\n",
      "    self._pdoc = pdfium.PdfDocument(self.path_or_stream)\n",
      "                 ^^^^^^^^^^^^^^^^^^^^^^^^^^^^^^^^^^^^^^^\n",
      "  File \"C:\\Users\\wurfil\\AppData\\Local\\Programs\\Python\\Python311\\Lib\\site-packages\\pypdfium2\\_helpers\\document.py\", line 78, in __init__\n",
      "    self.raw, to_hold, to_close = _open_pdf(self._input, self._password, self._autoclose)\n",
      "                                  ^^^^^^^^^^^^^^^^^^^^^^^^^^^^^^^^^^^^^^^^^^^^^^^^^^^^^^^\n",
      "  File \"C:\\Users\\wurfil\\AppData\\Local\\Programs\\Python\\Python311\\Lib\\site-packages\\pypdfium2\\_helpers\\document.py\", line 678, in _open_pdf\n",
      "    raise PdfiumError(f\"Failed to load document (PDFium: {pdfium_i.ErrorToStr.get(err_code)}).\")\n",
      "pypdfium2._helpers.misc.PdfiumError: Failed to load document (PDFium: Data format error).\n",
      "ERROR:root:Ошибка при обработке .\\input\\11.pdf: Input document input\\11.pdf is not valid.\n",
      "ERROR:docling.datamodel.document:An unexpected error occurred while opening the document 2.pdf\n",
      "Traceback (most recent call last):\n",
      "  File \"C:\\Users\\wurfil\\AppData\\Local\\Programs\\Python\\Python311\\Lib\\site-packages\\docling\\datamodel\\document.py\", line 120, in __init__\n",
      "    self._init_doc(backend, path_or_stream)\n",
      "  File \"C:\\Users\\wurfil\\AppData\\Local\\Programs\\Python\\Python311\\Lib\\site-packages\\docling\\datamodel\\document.py\", line 173, in _init_doc\n",
      "    self._backend = backend(self, path_or_stream=path_or_stream)\n",
      "                    ^^^^^^^^^^^^^^^^^^^^^^^^^^^^^^^^^^^^^^^^^^^^\n",
      "  File \"C:\\Users\\wurfil\\AppData\\Local\\Programs\\Python\\Python311\\Lib\\site-packages\\docling\\backend\\docling_parse_backend.py\", line 194, in __init__\n",
      "    self._pdoc = pdfium.PdfDocument(self.path_or_stream)\n",
      "                 ^^^^^^^^^^^^^^^^^^^^^^^^^^^^^^^^^^^^^^^\n",
      "  File \"C:\\Users\\wurfil\\AppData\\Local\\Programs\\Python\\Python311\\Lib\\site-packages\\pypdfium2\\_helpers\\document.py\", line 78, in __init__\n",
      "    self.raw, to_hold, to_close = _open_pdf(self._input, self._password, self._autoclose)\n",
      "                                  ^^^^^^^^^^^^^^^^^^^^^^^^^^^^^^^^^^^^^^^^^^^^^^^^^^^^^^^\n",
      "  File \"C:\\Users\\wurfil\\AppData\\Local\\Programs\\Python\\Python311\\Lib\\site-packages\\pypdfium2\\_helpers\\document.py\", line 678, in _open_pdf\n",
      "    raise PdfiumError(f\"Failed to load document (PDFium: {pdfium_i.ErrorToStr.get(err_code)}).\")\n",
      "pypdfium2._helpers.misc.PdfiumError: Failed to load document (PDFium: Data format error).\n",
      "ERROR:root:Ошибка при обработке .\\input\\2.pdf: Input document input\\2.pdf is not valid.\n",
      "ERROR:docling.datamodel.document:An unexpected error occurred while opening the document 24.pdf\n",
      "Traceback (most recent call last):\n",
      "  File \"C:\\Users\\wurfil\\AppData\\Local\\Programs\\Python\\Python311\\Lib\\site-packages\\docling\\datamodel\\document.py\", line 120, in __init__\n",
      "    self._init_doc(backend, path_or_stream)\n",
      "  File \"C:\\Users\\wurfil\\AppData\\Local\\Programs\\Python\\Python311\\Lib\\site-packages\\docling\\datamodel\\document.py\", line 173, in _init_doc\n",
      "    self._backend = backend(self, path_or_stream=path_or_stream)\n",
      "                    ^^^^^^^^^^^^^^^^^^^^^^^^^^^^^^^^^^^^^^^^^^^^\n",
      "  File \"C:\\Users\\wurfil\\AppData\\Local\\Programs\\Python\\Python311\\Lib\\site-packages\\docling\\backend\\docling_parse_backend.py\", line 194, in __init__\n",
      "    self._pdoc = pdfium.PdfDocument(self.path_or_stream)\n",
      "                 ^^^^^^^^^^^^^^^^^^^^^^^^^^^^^^^^^^^^^^^\n",
      "  File \"C:\\Users\\wurfil\\AppData\\Local\\Programs\\Python\\Python311\\Lib\\site-packages\\pypdfium2\\_helpers\\document.py\", line 78, in __init__\n",
      "    self.raw, to_hold, to_close = _open_pdf(self._input, self._password, self._autoclose)\n",
      "                                  ^^^^^^^^^^^^^^^^^^^^^^^^^^^^^^^^^^^^^^^^^^^^^^^^^^^^^^^\n",
      "  File \"C:\\Users\\wurfil\\AppData\\Local\\Programs\\Python\\Python311\\Lib\\site-packages\\pypdfium2\\_helpers\\document.py\", line 678, in _open_pdf\n",
      "    raise PdfiumError(f\"Failed to load document (PDFium: {pdfium_i.ErrorToStr.get(err_code)}).\")\n",
      "pypdfium2._helpers.misc.PdfiumError: Failed to load document (PDFium: Data format error).\n",
      "ERROR:root:Ошибка при обработке .\\input\\24.pdf: Input document input\\24.pdf is not valid.\n",
      "ERROR:docling.datamodel.document:An unexpected error occurred while opening the document 26.pdf\n",
      "Traceback (most recent call last):\n",
      "  File \"C:\\Users\\wurfil\\AppData\\Local\\Programs\\Python\\Python311\\Lib\\site-packages\\docling\\datamodel\\document.py\", line 120, in __init__\n",
      "    self._init_doc(backend, path_or_stream)\n",
      "  File \"C:\\Users\\wurfil\\AppData\\Local\\Programs\\Python\\Python311\\Lib\\site-packages\\docling\\datamodel\\document.py\", line 173, in _init_doc\n",
      "    self._backend = backend(self, path_or_stream=path_or_stream)\n",
      "                    ^^^^^^^^^^^^^^^^^^^^^^^^^^^^^^^^^^^^^^^^^^^^\n",
      "  File \"C:\\Users\\wurfil\\AppData\\Local\\Programs\\Python\\Python311\\Lib\\site-packages\\docling\\backend\\docling_parse_backend.py\", line 194, in __init__\n",
      "    self._pdoc = pdfium.PdfDocument(self.path_or_stream)\n",
      "                 ^^^^^^^^^^^^^^^^^^^^^^^^^^^^^^^^^^^^^^^\n",
      "  File \"C:\\Users\\wurfil\\AppData\\Local\\Programs\\Python\\Python311\\Lib\\site-packages\\pypdfium2\\_helpers\\document.py\", line 78, in __init__\n",
      "    self.raw, to_hold, to_close = _open_pdf(self._input, self._password, self._autoclose)\n",
      "                                  ^^^^^^^^^^^^^^^^^^^^^^^^^^^^^^^^^^^^^^^^^^^^^^^^^^^^^^^\n",
      "  File \"C:\\Users\\wurfil\\AppData\\Local\\Programs\\Python\\Python311\\Lib\\site-packages\\pypdfium2\\_helpers\\document.py\", line 678, in _open_pdf\n",
      "    raise PdfiumError(f\"Failed to load document (PDFium: {pdfium_i.ErrorToStr.get(err_code)}).\")\n",
      "pypdfium2._helpers.misc.PdfiumError: Failed to load document (PDFium: Data format error).\n",
      "ERROR:root:Ошибка при обработке .\\input\\26.pdf: Input document input\\26.pdf is not valid.\n",
      "ERROR:docling.datamodel.document:An unexpected error occurred while opening the document 27.pdf\n",
      "Traceback (most recent call last):\n",
      "  File \"C:\\Users\\wurfil\\AppData\\Local\\Programs\\Python\\Python311\\Lib\\site-packages\\docling\\datamodel\\document.py\", line 120, in __init__\n",
      "    self._init_doc(backend, path_or_stream)\n",
      "  File \"C:\\Users\\wurfil\\AppData\\Local\\Programs\\Python\\Python311\\Lib\\site-packages\\docling\\datamodel\\document.py\", line 173, in _init_doc\n",
      "    self._backend = backend(self, path_or_stream=path_or_stream)\n",
      "                    ^^^^^^^^^^^^^^^^^^^^^^^^^^^^^^^^^^^^^^^^^^^^\n",
      "  File \"C:\\Users\\wurfil\\AppData\\Local\\Programs\\Python\\Python311\\Lib\\site-packages\\docling\\backend\\docling_parse_backend.py\", line 194, in __init__\n",
      "    self._pdoc = pdfium.PdfDocument(self.path_or_stream)\n",
      "                 ^^^^^^^^^^^^^^^^^^^^^^^^^^^^^^^^^^^^^^^\n",
      "  File \"C:\\Users\\wurfil\\AppData\\Local\\Programs\\Python\\Python311\\Lib\\site-packages\\pypdfium2\\_helpers\\document.py\", line 78, in __init__\n",
      "    self.raw, to_hold, to_close = _open_pdf(self._input, self._password, self._autoclose)\n",
      "                                  ^^^^^^^^^^^^^^^^^^^^^^^^^^^^^^^^^^^^^^^^^^^^^^^^^^^^^^^\n",
      "  File \"C:\\Users\\wurfil\\AppData\\Local\\Programs\\Python\\Python311\\Lib\\site-packages\\pypdfium2\\_helpers\\document.py\", line 678, in _open_pdf\n",
      "    raise PdfiumError(f\"Failed to load document (PDFium: {pdfium_i.ErrorToStr.get(err_code)}).\")\n",
      "pypdfium2._helpers.misc.PdfiumError: Failed to load document (PDFium: Data format error).\n",
      "ERROR:root:Ошибка при обработке .\\input\\27.pdf: Input document input\\27.pdf is not valid.\n",
      "ERROR:docling.datamodel.document:An unexpected error occurred while opening the document 10.pdf\n",
      "Traceback (most recent call last):\n",
      "  File \"C:\\Users\\wurfil\\AppData\\Local\\Programs\\Python\\Python311\\Lib\\site-packages\\docling\\datamodel\\document.py\", line 120, in __init__\n",
      "    self._init_doc(backend, path_or_stream)\n",
      "  File \"C:\\Users\\wurfil\\AppData\\Local\\Programs\\Python\\Python311\\Lib\\site-packages\\docling\\datamodel\\document.py\", line 173, in _init_doc\n",
      "    self._backend = backend(self, path_or_stream=path_or_stream)\n",
      "                    ^^^^^^^^^^^^^^^^^^^^^^^^^^^^^^^^^^^^^^^^^^^^\n",
      "  File \"C:\\Users\\wurfil\\AppData\\Local\\Programs\\Python\\Python311\\Lib\\site-packages\\docling\\backend\\docling_parse_backend.py\", line 194, in __init__\n",
      "    self._pdoc = pdfium.PdfDocument(self.path_or_stream)\n",
      "                 ^^^^^^^^^^^^^^^^^^^^^^^^^^^^^^^^^^^^^^^\n",
      "  File \"C:\\Users\\wurfil\\AppData\\Local\\Programs\\Python\\Python311\\Lib\\site-packages\\pypdfium2\\_helpers\\document.py\", line 78, in __init__\n",
      "    self.raw, to_hold, to_close = _open_pdf(self._input, self._password, self._autoclose)\n",
      "                                  ^^^^^^^^^^^^^^^^^^^^^^^^^^^^^^^^^^^^^^^^^^^^^^^^^^^^^^^\n",
      "  File \"C:\\Users\\wurfil\\AppData\\Local\\Programs\\Python\\Python311\\Lib\\site-packages\\pypdfium2\\_helpers\\document.py\", line 678, in _open_pdf\n",
      "    raise PdfiumError(f\"Failed to load document (PDFium: {pdfium_i.ErrorToStr.get(err_code)}).\")\n",
      "pypdfium2._helpers.misc.PdfiumError: Failed to load document (PDFium: Data format error).\n",
      "ERROR:root:Ошибка при обработке .\\input\\10.pdf: Input document input\\10.pdf is not valid.\n",
      "ERROR:docling.datamodel.document:An unexpected error occurred while opening the document 23.pdf\n",
      "Traceback (most recent call last):\n",
      "  File \"C:\\Users\\wurfil\\AppData\\Local\\Programs\\Python\\Python311\\Lib\\site-packages\\docling\\datamodel\\document.py\", line 120, in __init__\n",
      "    self._init_doc(backend, path_or_stream)\n",
      "  File \"C:\\Users\\wurfil\\AppData\\Local\\Programs\\Python\\Python311\\Lib\\site-packages\\docling\\datamodel\\document.py\", line 173, in _init_doc\n",
      "    self._backend = backend(self, path_or_stream=path_or_stream)\n",
      "                    ^^^^^^^^^^^^^^^^^^^^^^^^^^^^^^^^^^^^^^^^^^^^\n",
      "  File \"C:\\Users\\wurfil\\AppData\\Local\\Programs\\Python\\Python311\\Lib\\site-packages\\docling\\backend\\docling_parse_backend.py\", line 194, in __init__\n",
      "    self._pdoc = pdfium.PdfDocument(self.path_or_stream)\n",
      "                 ^^^^^^^^^^^^^^^^^^^^^^^^^^^^^^^^^^^^^^^\n",
      "  File \"C:\\Users\\wurfil\\AppData\\Local\\Programs\\Python\\Python311\\Lib\\site-packages\\pypdfium2\\_helpers\\document.py\", line 78, in __init__\n",
      "    self.raw, to_hold, to_close = _open_pdf(self._input, self._password, self._autoclose)\n",
      "                                  ^^^^^^^^^^^^^^^^^^^^^^^^^^^^^^^^^^^^^^^^^^^^^^^^^^^^^^^\n",
      "  File \"C:\\Users\\wurfil\\AppData\\Local\\Programs\\Python\\Python311\\Lib\\site-packages\\pypdfium2\\_helpers\\document.py\", line 678, in _open_pdf\n",
      "    raise PdfiumError(f\"Failed to load document (PDFium: {pdfium_i.ErrorToStr.get(err_code)}).\")\n",
      "pypdfium2._helpers.misc.PdfiumError: Failed to load document (PDFium: Data format error).\n",
      "ERROR:root:Ошибка при обработке .\\input\\23.pdf: Input document input\\23.pdf is not valid.\n",
      "ERROR:docling.datamodel.document:An unexpected error occurred while opening the document 30.pdf\n",
      "Traceback (most recent call last):\n",
      "  File \"C:\\Users\\wurfil\\AppData\\Local\\Programs\\Python\\Python311\\Lib\\site-packages\\docling\\datamodel\\document.py\", line 120, in __init__\n",
      "    self._init_doc(backend, path_or_stream)\n",
      "  File \"C:\\Users\\wurfil\\AppData\\Local\\Programs\\Python\\Python311\\Lib\\site-packages\\docling\\datamodel\\document.py\", line 173, in _init_doc\n",
      "    self._backend = backend(self, path_or_stream=path_or_stream)\n",
      "                    ^^^^^^^^^^^^^^^^^^^^^^^^^^^^^^^^^^^^^^^^^^^^\n",
      "  File \"C:\\Users\\wurfil\\AppData\\Local\\Programs\\Python\\Python311\\Lib\\site-packages\\docling\\backend\\docling_parse_backend.py\", line 194, in __init__\n",
      "    self._pdoc = pdfium.PdfDocument(self.path_or_stream)\n",
      "                 ^^^^^^^^^^^^^^^^^^^^^^^^^^^^^^^^^^^^^^^\n",
      "  File \"C:\\Users\\wurfil\\AppData\\Local\\Programs\\Python\\Python311\\Lib\\site-packages\\pypdfium2\\_helpers\\document.py\", line 78, in __init__\n",
      "    self.raw, to_hold, to_close = _open_pdf(self._input, self._password, self._autoclose)\n",
      "                                  ^^^^^^^^^^^^^^^^^^^^^^^^^^^^^^^^^^^^^^^^^^^^^^^^^^^^^^^\n",
      "  File \"C:\\Users\\wurfil\\AppData\\Local\\Programs\\Python\\Python311\\Lib\\site-packages\\pypdfium2\\_helpers\\document.py\", line 678, in _open_pdf\n",
      "    raise PdfiumError(f\"Failed to load document (PDFium: {pdfium_i.ErrorToStr.get(err_code)}).\")\n",
      "pypdfium2._helpers.misc.PdfiumError: Failed to load document (PDFium: Data format error).\n",
      "ERROR:root:Ошибка при обработке .\\input\\30.pdf: Input document input\\30.pdf is not valid.\n",
      "ERROR:docling.datamodel.document:An unexpected error occurred while opening the document 3.pdf\n",
      "Traceback (most recent call last):\n",
      "  File \"C:\\Users\\wurfil\\AppData\\Local\\Programs\\Python\\Python311\\Lib\\site-packages\\docling\\datamodel\\document.py\", line 120, in __init__\n",
      "    self._init_doc(backend, path_or_stream)\n",
      "  File \"C:\\Users\\wurfil\\AppData\\Local\\Programs\\Python\\Python311\\Lib\\site-packages\\docling\\datamodel\\document.py\", line 173, in _init_doc\n",
      "    self._backend = backend(self, path_or_stream=path_or_stream)\n",
      "                    ^^^^^^^^^^^^^^^^^^^^^^^^^^^^^^^^^^^^^^^^^^^^\n",
      "  File \"C:\\Users\\wurfil\\AppData\\Local\\Programs\\Python\\Python311\\Lib\\site-packages\\docling\\backend\\docling_parse_backend.py\", line 194, in __init__\n",
      "    self._pdoc = pdfium.PdfDocument(self.path_or_stream)\n",
      "                 ^^^^^^^^^^^^^^^^^^^^^^^^^^^^^^^^^^^^^^^\n",
      "  File \"C:\\Users\\wurfil\\AppData\\Local\\Programs\\Python\\Python311\\Lib\\site-packages\\pypdfium2\\_helpers\\document.py\", line 78, in __init__\n",
      "    self.raw, to_hold, to_close = _open_pdf(self._input, self._password, self._autoclose)\n",
      "                                  ^^^^^^^^^^^^^^^^^^^^^^^^^^^^^^^^^^^^^^^^^^^^^^^^^^^^^^^\n",
      "  File \"C:\\Users\\wurfil\\AppData\\Local\\Programs\\Python\\Python311\\Lib\\site-packages\\pypdfium2\\_helpers\\document.py\", line 678, in _open_pdf\n",
      "    raise PdfiumError(f\"Failed to load document (PDFium: {pdfium_i.ErrorToStr.get(err_code)}).\")\n",
      "pypdfium2._helpers.misc.PdfiumError: Failed to load document (PDFium: Data format error).\n",
      "ERROR:root:Ошибка при обработке .\\input\\3.pdf: Input document input\\3.pdf is not valid.\n",
      "ERROR:docling.datamodel.document:An unexpected error occurred while opening the document 31.pdf\n",
      "Traceback (most recent call last):\n",
      "  File \"C:\\Users\\wurfil\\AppData\\Local\\Programs\\Python\\Python311\\Lib\\site-packages\\docling\\datamodel\\document.py\", line 120, in __init__\n",
      "    self._init_doc(backend, path_or_stream)\n",
      "  File \"C:\\Users\\wurfil\\AppData\\Local\\Programs\\Python\\Python311\\Lib\\site-packages\\docling\\datamodel\\document.py\", line 173, in _init_doc\n",
      "    self._backend = backend(self, path_or_stream=path_or_stream)\n",
      "                    ^^^^^^^^^^^^^^^^^^^^^^^^^^^^^^^^^^^^^^^^^^^^\n",
      "  File \"C:\\Users\\wurfil\\AppData\\Local\\Programs\\Python\\Python311\\Lib\\site-packages\\docling\\backend\\docling_parse_backend.py\", line 194, in __init__\n",
      "    self._pdoc = pdfium.PdfDocument(self.path_or_stream)\n",
      "                 ^^^^^^^^^^^^^^^^^^^^^^^^^^^^^^^^^^^^^^^\n",
      "  File \"C:\\Users\\wurfil\\AppData\\Local\\Programs\\Python\\Python311\\Lib\\site-packages\\pypdfium2\\_helpers\\document.py\", line 78, in __init__\n",
      "    self.raw, to_hold, to_close = _open_pdf(self._input, self._password, self._autoclose)\n",
      "                                  ^^^^^^^^^^^^^^^^^^^^^^^^^^^^^^^^^^^^^^^^^^^^^^^^^^^^^^^\n",
      "  File \"C:\\Users\\wurfil\\AppData\\Local\\Programs\\Python\\Python311\\Lib\\site-packages\\pypdfium2\\_helpers\\document.py\", line 678, in _open_pdf\n",
      "    raise PdfiumError(f\"Failed to load document (PDFium: {pdfium_i.ErrorToStr.get(err_code)}).\")\n",
      "pypdfium2._helpers.misc.PdfiumError: Failed to load document (PDFium: Data format error).\n",
      "ERROR:root:Ошибка при обработке .\\input\\31.pdf: Input document input\\31.pdf is not valid.\n",
      "ERROR:docling.datamodel.document:An unexpected error occurred while opening the document 25.pdf\n",
      "Traceback (most recent call last):\n",
      "  File \"C:\\Users\\wurfil\\AppData\\Local\\Programs\\Python\\Python311\\Lib\\site-packages\\docling\\datamodel\\document.py\", line 120, in __init__\n",
      "    self._init_doc(backend, path_or_stream)\n",
      "  File \"C:\\Users\\wurfil\\AppData\\Local\\Programs\\Python\\Python311\\Lib\\site-packages\\docling\\datamodel\\document.py\", line 173, in _init_doc\n",
      "    self._backend = backend(self, path_or_stream=path_or_stream)\n",
      "                    ^^^^^^^^^^^^^^^^^^^^^^^^^^^^^^^^^^^^^^^^^^^^\n",
      "  File \"C:\\Users\\wurfil\\AppData\\Local\\Programs\\Python\\Python311\\Lib\\site-packages\\docling\\backend\\docling_parse_backend.py\", line 194, in __init__\n",
      "    self._pdoc = pdfium.PdfDocument(self.path_or_stream)\n",
      "                 ^^^^^^^^^^^^^^^^^^^^^^^^^^^^^^^^^^^^^^^\n",
      "  File \"C:\\Users\\wurfil\\AppData\\Local\\Programs\\Python\\Python311\\Lib\\site-packages\\pypdfium2\\_helpers\\document.py\", line 78, in __init__\n",
      "    self.raw, to_hold, to_close = _open_pdf(self._input, self._password, self._autoclose)\n",
      "                                  ^^^^^^^^^^^^^^^^^^^^^^^^^^^^^^^^^^^^^^^^^^^^^^^^^^^^^^^\n",
      "  File \"C:\\Users\\wurfil\\AppData\\Local\\Programs\\Python\\Python311\\Lib\\site-packages\\pypdfium2\\_helpers\\document.py\", line 678, in _open_pdf\n",
      "    raise PdfiumError(f\"Failed to load document (PDFium: {pdfium_i.ErrorToStr.get(err_code)}).\")\n",
      "pypdfium2._helpers.misc.PdfiumError: Failed to load document (PDFium: Data format error).\n",
      "ERROR:root:Ошибка при обработке .\\input\\25.pdf: Input document input\\25.pdf is not valid.\n",
      "ERROR:docling.datamodel.document:An unexpected error occurred while opening the document 33.pdf\n",
      "Traceback (most recent call last):\n",
      "  File \"C:\\Users\\wurfil\\AppData\\Local\\Programs\\Python\\Python311\\Lib\\site-packages\\docling\\datamodel\\document.py\", line 120, in __init__\n",
      "    self._init_doc(backend, path_or_stream)\n",
      "  File \"C:\\Users\\wurfil\\AppData\\Local\\Programs\\Python\\Python311\\Lib\\site-packages\\docling\\datamodel\\document.py\", line 173, in _init_doc\n",
      "    self._backend = backend(self, path_or_stream=path_or_stream)\n",
      "                    ^^^^^^^^^^^^^^^^^^^^^^^^^^^^^^^^^^^^^^^^^^^^\n",
      "  File \"C:\\Users\\wurfil\\AppData\\Local\\Programs\\Python\\Python311\\Lib\\site-packages\\docling\\backend\\docling_parse_backend.py\", line 194, in __init__\n",
      "    self._pdoc = pdfium.PdfDocument(self.path_or_stream)\n",
      "                 ^^^^^^^^^^^^^^^^^^^^^^^^^^^^^^^^^^^^^^^\n",
      "  File \"C:\\Users\\wurfil\\AppData\\Local\\Programs\\Python\\Python311\\Lib\\site-packages\\pypdfium2\\_helpers\\document.py\", line 78, in __init__\n",
      "    self.raw, to_hold, to_close = _open_pdf(self._input, self._password, self._autoclose)\n",
      "                                  ^^^^^^^^^^^^^^^^^^^^^^^^^^^^^^^^^^^^^^^^^^^^^^^^^^^^^^^\n",
      "  File \"C:\\Users\\wurfil\\AppData\\Local\\Programs\\Python\\Python311\\Lib\\site-packages\\pypdfium2\\_helpers\\document.py\", line 678, in _open_pdf\n",
      "    raise PdfiumError(f\"Failed to load document (PDFium: {pdfium_i.ErrorToStr.get(err_code)}).\")\n",
      "pypdfium2._helpers.misc.PdfiumError: Failed to load document (PDFium: Data format error).\n",
      "ERROR:root:Ошибка при обработке .\\input\\33.pdf: Input document input\\33.pdf is not valid.\n",
      "ERROR:docling.datamodel.document:An unexpected error occurred while opening the document 34.pdf\n",
      "Traceback (most recent call last):\n",
      "  File \"C:\\Users\\wurfil\\AppData\\Local\\Programs\\Python\\Python311\\Lib\\site-packages\\docling\\datamodel\\document.py\", line 120, in __init__\n",
      "    self._init_doc(backend, path_or_stream)\n",
      "  File \"C:\\Users\\wurfil\\AppData\\Local\\Programs\\Python\\Python311\\Lib\\site-packages\\docling\\datamodel\\document.py\", line 173, in _init_doc\n",
      "    self._backend = backend(self, path_or_stream=path_or_stream)\n",
      "                    ^^^^^^^^^^^^^^^^^^^^^^^^^^^^^^^^^^^^^^^^^^^^\n",
      "  File \"C:\\Users\\wurfil\\AppData\\Local\\Programs\\Python\\Python311\\Lib\\site-packages\\docling\\backend\\docling_parse_backend.py\", line 194, in __init__\n",
      "    self._pdoc = pdfium.PdfDocument(self.path_or_stream)\n",
      "                 ^^^^^^^^^^^^^^^^^^^^^^^^^^^^^^^^^^^^^^^\n",
      "  File \"C:\\Users\\wurfil\\AppData\\Local\\Programs\\Python\\Python311\\Lib\\site-packages\\pypdfium2\\_helpers\\document.py\", line 78, in __init__\n",
      "    self.raw, to_hold, to_close = _open_pdf(self._input, self._password, self._autoclose)\n",
      "                                  ^^^^^^^^^^^^^^^^^^^^^^^^^^^^^^^^^^^^^^^^^^^^^^^^^^^^^^^\n",
      "  File \"C:\\Users\\wurfil\\AppData\\Local\\Programs\\Python\\Python311\\Lib\\site-packages\\pypdfium2\\_helpers\\document.py\", line 678, in _open_pdf\n",
      "    raise PdfiumError(f\"Failed to load document (PDFium: {pdfium_i.ErrorToStr.get(err_code)}).\")\n",
      "pypdfium2._helpers.misc.PdfiumError: Failed to load document (PDFium: Data format error).\n",
      "ERROR:root:Ошибка при обработке .\\input\\34.pdf: Input document input\\34.pdf is not valid.\n",
      "ERROR:docling.datamodel.document:An unexpected error occurred while opening the document 28.pdf\n",
      "Traceback (most recent call last):\n",
      "  File \"C:\\Users\\wurfil\\AppData\\Local\\Programs\\Python\\Python311\\Lib\\site-packages\\docling\\datamodel\\document.py\", line 120, in __init__\n",
      "    self._init_doc(backend, path_or_stream)\n",
      "  File \"C:\\Users\\wurfil\\AppData\\Local\\Programs\\Python\\Python311\\Lib\\site-packages\\docling\\datamodel\\document.py\", line 173, in _init_doc\n",
      "    self._backend = backend(self, path_or_stream=path_or_stream)\n",
      "                    ^^^^^^^^^^^^^^^^^^^^^^^^^^^^^^^^^^^^^^^^^^^^\n",
      "  File \"C:\\Users\\wurfil\\AppData\\Local\\Programs\\Python\\Python311\\Lib\\site-packages\\docling\\backend\\docling_parse_backend.py\", line 194, in __init__\n",
      "    self._pdoc = pdfium.PdfDocument(self.path_or_stream)\n",
      "                 ^^^^^^^^^^^^^^^^^^^^^^^^^^^^^^^^^^^^^^^\n",
      "  File \"C:\\Users\\wurfil\\AppData\\Local\\Programs\\Python\\Python311\\Lib\\site-packages\\pypdfium2\\_helpers\\document.py\", line 78, in __init__\n",
      "    self.raw, to_hold, to_close = _open_pdf(self._input, self._password, self._autoclose)\n",
      "                                  ^^^^^^^^^^^^^^^^^^^^^^^^^^^^^^^^^^^^^^^^^^^^^^^^^^^^^^^\n",
      "  File \"C:\\Users\\wurfil\\AppData\\Local\\Programs\\Python\\Python311\\Lib\\site-packages\\pypdfium2\\_helpers\\document.py\", line 678, in _open_pdf\n",
      "    raise PdfiumError(f\"Failed to load document (PDFium: {pdfium_i.ErrorToStr.get(err_code)}).\")\n",
      "pypdfium2._helpers.misc.PdfiumError: Failed to load document (PDFium: Data format error).\n",
      "ERROR:root:Ошибка при обработке .\\input\\28.pdf: Input document input\\28.pdf is not valid.\n",
      "ERROR:docling.datamodel.document:An unexpected error occurred while opening the document 35.pdf\n",
      "Traceback (most recent call last):\n",
      "  File \"C:\\Users\\wurfil\\AppData\\Local\\Programs\\Python\\Python311\\Lib\\site-packages\\docling\\datamodel\\document.py\", line 120, in __init__\n",
      "    self._init_doc(backend, path_or_stream)\n",
      "  File \"C:\\Users\\wurfil\\AppData\\Local\\Programs\\Python\\Python311\\Lib\\site-packages\\docling\\datamodel\\document.py\", line 173, in _init_doc\n",
      "    self._backend = backend(self, path_or_stream=path_or_stream)\n",
      "                    ^^^^^^^^^^^^^^^^^^^^^^^^^^^^^^^^^^^^^^^^^^^^\n",
      "  File \"C:\\Users\\wurfil\\AppData\\Local\\Programs\\Python\\Python311\\Lib\\site-packages\\docling\\backend\\docling_parse_backend.py\", line 194, in __init__\n",
      "    self._pdoc = pdfium.PdfDocument(self.path_or_stream)\n",
      "                 ^^^^^^^^^^^^^^^^^^^^^^^^^^^^^^^^^^^^^^^\n",
      "  File \"C:\\Users\\wurfil\\AppData\\Local\\Programs\\Python\\Python311\\Lib\\site-packages\\pypdfium2\\_helpers\\document.py\", line 78, in __init__\n",
      "    self.raw, to_hold, to_close = _open_pdf(self._input, self._password, self._autoclose)\n",
      "                                  ^^^^^^^^^^^^^^^^^^^^^^^^^^^^^^^^^^^^^^^^^^^^^^^^^^^^^^^\n",
      "  File \"C:\\Users\\wurfil\\AppData\\Local\\Programs\\Python\\Python311\\Lib\\site-packages\\pypdfium2\\_helpers\\document.py\", line 678, in _open_pdf\n",
      "    raise PdfiumError(f\"Failed to load document (PDFium: {pdfium_i.ErrorToStr.get(err_code)}).\")\n",
      "pypdfium2._helpers.misc.PdfiumError: Failed to load document (PDFium: Data format error).\n",
      "ERROR:docling.datamodel.document:An unexpected error occurred while opening the document 36.pdf\n",
      "Traceback (most recent call last):\n",
      "  File \"C:\\Users\\wurfil\\AppData\\Local\\Programs\\Python\\Python311\\Lib\\site-packages\\docling\\datamodel\\document.py\", line 120, in __init__\n",
      "    self._init_doc(backend, path_or_stream)\n",
      "  File \"C:\\Users\\wurfil\\AppData\\Local\\Programs\\Python\\Python311\\Lib\\site-packages\\docling\\datamodel\\document.py\", line 173, in _init_doc\n",
      "    self._backend = backend(self, path_or_stream=path_or_stream)\n",
      "                    ^^^^^^^^^^^^^^^^^^^^^^^^^^^^^^^^^^^^^^^^^^^^\n",
      "  File \"C:\\Users\\wurfil\\AppData\\Local\\Programs\\Python\\Python311\\Lib\\site-packages\\docling\\backend\\docling_parse_backend.py\", line 194, in __init__\n",
      "    self._pdoc = pdfium.PdfDocument(self.path_or_stream)\n",
      "                 ^^^^^^^^^^^^^^^^^^^^^^^^^^^^^^^^^^^^^^^\n",
      "  File \"C:\\Users\\wurfil\\AppData\\Local\\Programs\\Python\\Python311\\Lib\\site-packages\\pypdfium2\\_helpers\\document.py\", line 78, in __init__\n",
      "    self.raw, to_hold, to_close = _open_pdf(self._input, self._password, self._autoclose)\n",
      "                                  ^^^^^^^^^^^^^^^^^^^^^^^^^^^^^^^^^^^^^^^^^^^^^^^^^^^^^^^\n",
      "  File \"C:\\Users\\wurfil\\AppData\\Local\\Programs\\Python\\Python311\\Lib\\site-packages\\pypdfium2\\_helpers\\document.py\", line 678, in _open_pdf\n",
      "    raise PdfiumError(f\"Failed to load document (PDFium: {pdfium_i.ErrorToStr.get(err_code)}).\")\n",
      "pypdfium2._helpers.misc.PdfiumError: Failed to load document (PDFium: Data format error).\n",
      "ERROR:root:Ошибка при обработке .\\input\\35.pdf: Input document input\\35.pdf is not valid.\n",
      "ERROR:root:Ошибка при обработке .\\input\\36.pdf: Input document input\\36.pdf is not valid.\n",
      "ERROR:docling.datamodel.document:An unexpected error occurred while opening the document 38.pdf\n",
      "Traceback (most recent call last):\n",
      "  File \"C:\\Users\\wurfil\\AppData\\Local\\Programs\\Python\\Python311\\Lib\\site-packages\\docling\\datamodel\\document.py\", line 120, in __init__\n",
      "    self._init_doc(backend, path_or_stream)\n",
      "  File \"C:\\Users\\wurfil\\AppData\\Local\\Programs\\Python\\Python311\\Lib\\site-packages\\docling\\datamodel\\document.py\", line 173, in _init_doc\n",
      "    self._backend = backend(self, path_or_stream=path_or_stream)\n",
      "                    ^^^^^^^^^^^^^^^^^^^^^^^^^^^^^^^^^^^^^^^^^^^^\n",
      "  File \"C:\\Users\\wurfil\\AppData\\Local\\Programs\\Python\\Python311\\Lib\\site-packages\\docling\\backend\\docling_parse_backend.py\", line 194, in __init__\n",
      "    self._pdoc = pdfium.PdfDocument(self.path_or_stream)\n",
      "                 ^^^^^^^^^^^^^^^^^^^^^^^^^^^^^^^^^^^^^^^\n",
      "  File \"C:\\Users\\wurfil\\AppData\\Local\\Programs\\Python\\Python311\\Lib\\site-packages\\pypdfium2\\_helpers\\document.py\", line 78, in __init__\n",
      "    self.raw, to_hold, to_close = _open_pdf(self._input, self._password, self._autoclose)\n",
      "                                  ^^^^^^^^^^^^^^^^^^^^^^^^^^^^^^^^^^^^^^^^^^^^^^^^^^^^^^^\n",
      "  File \"C:\\Users\\wurfil\\AppData\\Local\\Programs\\Python\\Python311\\Lib\\site-packages\\pypdfium2\\_helpers\\document.py\", line 678, in _open_pdf\n",
      "    raise PdfiumError(f\"Failed to load document (PDFium: {pdfium_i.ErrorToStr.get(err_code)}).\")\n",
      "pypdfium2._helpers.misc.PdfiumError: Failed to load document (PDFium: Data format error).\n",
      "ERROR:root:Ошибка при обработке .\\input\\38.pdf: Input document input\\38.pdf is not valid.\n",
      "ERROR:docling.datamodel.document:An unexpected error occurred while opening the document 37.pdf\n",
      "Traceback (most recent call last):\n",
      "  File \"C:\\Users\\wurfil\\AppData\\Local\\Programs\\Python\\Python311\\Lib\\site-packages\\docling\\datamodel\\document.py\", line 120, in __init__\n",
      "    self._init_doc(backend, path_or_stream)\n",
      "  File \"C:\\Users\\wurfil\\AppData\\Local\\Programs\\Python\\Python311\\Lib\\site-packages\\docling\\datamodel\\document.py\", line 173, in _init_doc\n",
      "    self._backend = backend(self, path_or_stream=path_or_stream)\n",
      "                    ^^^^^^^^^^^^^^^^^^^^^^^^^^^^^^^^^^^^^^^^^^^^\n",
      "  File \"C:\\Users\\wurfil\\AppData\\Local\\Programs\\Python\\Python311\\Lib\\site-packages\\docling\\backend\\docling_parse_backend.py\", line 194, in __init__\n",
      "    self._pdoc = pdfium.PdfDocument(self.path_or_stream)\n",
      "                 ^^^^^^^^^^^^^^^^^^^^^^^^^^^^^^^^^^^^^^^\n",
      "  File \"C:\\Users\\wurfil\\AppData\\Local\\Programs\\Python\\Python311\\Lib\\site-packages\\pypdfium2\\_helpers\\document.py\", line 78, in __init__\n",
      "    self.raw, to_hold, to_close = _open_pdf(self._input, self._password, self._autoclose)\n",
      "                                  ^^^^^^^^^^^^^^^^^^^^^^^^^^^^^^^^^^^^^^^^^^^^^^^^^^^^^^^\n",
      "  File \"C:\\Users\\wurfil\\AppData\\Local\\Programs\\Python\\Python311\\Lib\\site-packages\\pypdfium2\\_helpers\\document.py\", line 678, in _open_pdf\n",
      "    raise PdfiumError(f\"Failed to load document (PDFium: {pdfium_i.ErrorToStr.get(err_code)}).\")\n",
      "pypdfium2._helpers.misc.PdfiumError: Failed to load document (PDFium: Data format error).\n",
      "ERROR:root:Ошибка при обработке .\\input\\37.pdf: Input document input\\37.pdf is not valid.\n",
      "ERROR:docling.datamodel.document:An unexpected error occurred while opening the document 32.pdf\n",
      "Traceback (most recent call last):\n",
      "  File \"C:\\Users\\wurfil\\AppData\\Local\\Programs\\Python\\Python311\\Lib\\site-packages\\docling\\datamodel\\document.py\", line 120, in __init__\n",
      "    self._init_doc(backend, path_or_stream)\n",
      "  File \"C:\\Users\\wurfil\\AppData\\Local\\Programs\\Python\\Python311\\Lib\\site-packages\\docling\\datamodel\\document.py\", line 173, in _init_doc\n",
      "    self._backend = backend(self, path_or_stream=path_or_stream)\n",
      "                    ^^^^^^^^^^^^^^^^^^^^^^^^^^^^^^^^^^^^^^^^^^^^\n",
      "  File \"C:\\Users\\wurfil\\AppData\\Local\\Programs\\Python\\Python311\\Lib\\site-packages\\docling\\backend\\docling_parse_backend.py\", line 194, in __init__\n",
      "    self._pdoc = pdfium.PdfDocument(self.path_or_stream)\n",
      "                 ^^^^^^^^^^^^^^^^^^^^^^^^^^^^^^^^^^^^^^^\n",
      "  File \"C:\\Users\\wurfil\\AppData\\Local\\Programs\\Python\\Python311\\Lib\\site-packages\\pypdfium2\\_helpers\\document.py\", line 78, in __init__\n",
      "    self.raw, to_hold, to_close = _open_pdf(self._input, self._password, self._autoclose)\n",
      "                                  ^^^^^^^^^^^^^^^^^^^^^^^^^^^^^^^^^^^^^^^^^^^^^^^^^^^^^^^\n",
      "  File \"C:\\Users\\wurfil\\AppData\\Local\\Programs\\Python\\Python311\\Lib\\site-packages\\pypdfium2\\_helpers\\document.py\", line 678, in _open_pdf\n",
      "    raise PdfiumError(f\"Failed to load document (PDFium: {pdfium_i.ErrorToStr.get(err_code)}).\")\n",
      "pypdfium2._helpers.misc.PdfiumError: Failed to load document (PDFium: Data format error).\n",
      "ERROR:root:Ошибка при обработке .\\input\\32.pdf: Input document input\\32.pdf is not valid.\n",
      "ERROR:docling.datamodel.document:An unexpected error occurred while opening the document 41.pdf\n",
      "Traceback (most recent call last):\n",
      "  File \"C:\\Users\\wurfil\\AppData\\Local\\Programs\\Python\\Python311\\Lib\\site-packages\\docling\\datamodel\\document.py\", line 120, in __init__\n",
      "    self._init_doc(backend, path_or_stream)\n",
      "  File \"C:\\Users\\wurfil\\AppData\\Local\\Programs\\Python\\Python311\\Lib\\site-packages\\docling\\datamodel\\document.py\", line 173, in _init_doc\n",
      "    self._backend = backend(self, path_or_stream=path_or_stream)\n",
      "                    ^^^^^^^^^^^^^^^^^^^^^^^^^^^^^^^^^^^^^^^^^^^^\n",
      "  File \"C:\\Users\\wurfil\\AppData\\Local\\Programs\\Python\\Python311\\Lib\\site-packages\\docling\\backend\\docling_parse_backend.py\", line 194, in __init__\n",
      "    self._pdoc = pdfium.PdfDocument(self.path_or_stream)\n",
      "                 ^^^^^^^^^^^^^^^^^^^^^^^^^^^^^^^^^^^^^^^\n",
      "  File \"C:\\Users\\wurfil\\AppData\\Local\\Programs\\Python\\Python311\\Lib\\site-packages\\pypdfium2\\_helpers\\document.py\", line 78, in __init__\n",
      "    self.raw, to_hold, to_close = _open_pdf(self._input, self._password, self._autoclose)\n",
      "                                  ^^^^^^^^^^^^^^^^^^^^^^^^^^^^^^^^^^^^^^^^^^^^^^^^^^^^^^^\n",
      "  File \"C:\\Users\\wurfil\\AppData\\Local\\Programs\\Python\\Python311\\Lib\\site-packages\\pypdfium2\\_helpers\\document.py\", line 678, in _open_pdf\n",
      "    raise PdfiumError(f\"Failed to load document (PDFium: {pdfium_i.ErrorToStr.get(err_code)}).\")\n",
      "pypdfium2._helpers.misc.PdfiumError: Failed to load document (PDFium: Data format error).\n",
      "ERROR:root:Ошибка при обработке .\\input\\41.pdf: Input document input\\41.pdf is not valid.\n",
      "ERROR:docling.datamodel.document:An unexpected error occurred while opening the document 42.pdf\n",
      "Traceback (most recent call last):\n",
      "  File \"C:\\Users\\wurfil\\AppData\\Local\\Programs\\Python\\Python311\\Lib\\site-packages\\docling\\datamodel\\document.py\", line 120, in __init__\n",
      "    self._init_doc(backend, path_or_stream)\n",
      "  File \"C:\\Users\\wurfil\\AppData\\Local\\Programs\\Python\\Python311\\Lib\\site-packages\\docling\\datamodel\\document.py\", line 173, in _init_doc\n",
      "    self._backend = backend(self, path_or_stream=path_or_stream)\n",
      "                    ^^^^^^^^^^^^^^^^^^^^^^^^^^^^^^^^^^^^^^^^^^^^\n",
      "  File \"C:\\Users\\wurfil\\AppData\\Local\\Programs\\Python\\Python311\\Lib\\site-packages\\docling\\backend\\docling_parse_backend.py\", line 194, in __init__\n",
      "    self._pdoc = pdfium.PdfDocument(self.path_or_stream)\n",
      "                 ^^^^^^^^^^^^^^^^^^^^^^^^^^^^^^^^^^^^^^^\n",
      "  File \"C:\\Users\\wurfil\\AppData\\Local\\Programs\\Python\\Python311\\Lib\\site-packages\\pypdfium2\\_helpers\\document.py\", line 78, in __init__\n",
      "    self.raw, to_hold, to_close = _open_pdf(self._input, self._password, self._autoclose)\n",
      "                                  ^^^^^^^^^^^^^^^^^^^^^^^^^^^^^^^^^^^^^^^^^^^^^^^^^^^^^^^\n",
      "  File \"C:\\Users\\wurfil\\AppData\\Local\\Programs\\Python\\Python311\\Lib\\site-packages\\pypdfium2\\_helpers\\document.py\", line 678, in _open_pdf\n",
      "    raise PdfiumError(f\"Failed to load document (PDFium: {pdfium_i.ErrorToStr.get(err_code)}).\")\n",
      "pypdfium2._helpers.misc.PdfiumError: Failed to load document (PDFium: Data format error).\n",
      "ERROR:root:Ошибка при обработке .\\input\\42.pdf: Input document input\\42.pdf is not valid.\n",
      "ERROR:docling.datamodel.document:An unexpected error occurred while opening the document 43.pdf\n",
      "Traceback (most recent call last):\n",
      "  File \"C:\\Users\\wurfil\\AppData\\Local\\Programs\\Python\\Python311\\Lib\\site-packages\\docling\\datamodel\\document.py\", line 120, in __init__\n",
      "    self._init_doc(backend, path_or_stream)\n",
      "  File \"C:\\Users\\wurfil\\AppData\\Local\\Programs\\Python\\Python311\\Lib\\site-packages\\docling\\datamodel\\document.py\", line 173, in _init_doc\n",
      "    self._backend = backend(self, path_or_stream=path_or_stream)\n",
      "                    ^^^^^^^^^^^^^^^^^^^^^^^^^^^^^^^^^^^^^^^^^^^^\n",
      "  File \"C:\\Users\\wurfil\\AppData\\Local\\Programs\\Python\\Python311\\Lib\\site-packages\\docling\\backend\\docling_parse_backend.py\", line 194, in __init__\n",
      "    self._pdoc = pdfium.PdfDocument(self.path_or_stream)\n",
      "                 ^^^^^^^^^^^^^^^^^^^^^^^^^^^^^^^^^^^^^^^\n",
      "  File \"C:\\Users\\wurfil\\AppData\\Local\\Programs\\Python\\Python311\\Lib\\site-packages\\pypdfium2\\_helpers\\document.py\", line 78, in __init__\n",
      "    self.raw, to_hold, to_close = _open_pdf(self._input, self._password, self._autoclose)\n",
      "                                  ^^^^^^^^^^^^^^^^^^^^^^^^^^^^^^^^^^^^^^^^^^^^^^^^^^^^^^^\n",
      "  File \"C:\\Users\\wurfil\\AppData\\Local\\Programs\\Python\\Python311\\Lib\\site-packages\\pypdfium2\\_helpers\\document.py\", line 678, in _open_pdf\n",
      "    raise PdfiumError(f\"Failed to load document (PDFium: {pdfium_i.ErrorToStr.get(err_code)}).\")\n",
      "pypdfium2._helpers.misc.PdfiumError: Failed to load document (PDFium: Data format error).\n",
      "ERROR:root:Ошибка при обработке .\\input\\43.pdf: Input document input\\43.pdf is not valid.\n",
      "ERROR:docling.datamodel.document:An unexpected error occurred while opening the document 39.pdf\n",
      "Traceback (most recent call last):\n",
      "  File \"C:\\Users\\wurfil\\AppData\\Local\\Programs\\Python\\Python311\\Lib\\site-packages\\docling\\datamodel\\document.py\", line 120, in __init__\n",
      "    self._init_doc(backend, path_or_stream)\n",
      "  File \"C:\\Users\\wurfil\\AppData\\Local\\Programs\\Python\\Python311\\Lib\\site-packages\\docling\\datamodel\\document.py\", line 173, in _init_doc\n",
      "    self._backend = backend(self, path_or_stream=path_or_stream)\n",
      "                    ^^^^^^^^^^^^^^^^^^^^^^^^^^^^^^^^^^^^^^^^^^^^\n",
      "  File \"C:\\Users\\wurfil\\AppData\\Local\\Programs\\Python\\Python311\\Lib\\site-packages\\docling\\backend\\docling_parse_backend.py\", line 194, in __init__\n",
      "    self._pdoc = pdfium.PdfDocument(self.path_or_stream)\n",
      "                 ^^^^^^^^^^^^^^^^^^^^^^^^^^^^^^^^^^^^^^^\n",
      "  File \"C:\\Users\\wurfil\\AppData\\Local\\Programs\\Python\\Python311\\Lib\\site-packages\\pypdfium2\\_helpers\\document.py\", line 78, in __init__\n",
      "    self.raw, to_hold, to_close = _open_pdf(self._input, self._password, self._autoclose)\n",
      "                                  ^^^^^^^^^^^^^^^^^^^^^^^^^^^^^^^^^^^^^^^^^^^^^^^^^^^^^^^\n",
      "  File \"C:\\Users\\wurfil\\AppData\\Local\\Programs\\Python\\Python311\\Lib\\site-packages\\pypdfium2\\_helpers\\document.py\", line 678, in _open_pdf\n",
      "    raise PdfiumError(f\"Failed to load document (PDFium: {pdfium_i.ErrorToStr.get(err_code)}).\")\n",
      "pypdfium2._helpers.misc.PdfiumError: Failed to load document (PDFium: Data format error).\n",
      "ERROR:root:Ошибка при обработке .\\input\\39.pdf: Input document input\\39.pdf is not valid.\n",
      "ERROR:docling.datamodel.document:An unexpected error occurred while opening the document 4.pdf\n",
      "Traceback (most recent call last):\n",
      "  File \"C:\\Users\\wurfil\\AppData\\Local\\Programs\\Python\\Python311\\Lib\\site-packages\\docling\\datamodel\\document.py\", line 120, in __init__\n",
      "    self._init_doc(backend, path_or_stream)\n",
      "  File \"C:\\Users\\wurfil\\AppData\\Local\\Programs\\Python\\Python311\\Lib\\site-packages\\docling\\datamodel\\document.py\", line 173, in _init_doc\n",
      "    self._backend = backend(self, path_or_stream=path_or_stream)\n",
      "                    ^^^^^^^^^^^^^^^^^^^^^^^^^^^^^^^^^^^^^^^^^^^^\n",
      "  File \"C:\\Users\\wurfil\\AppData\\Local\\Programs\\Python\\Python311\\Lib\\site-packages\\docling\\backend\\docling_parse_backend.py\", line 194, in __init__\n",
      "    self._pdoc = pdfium.PdfDocument(self.path_or_stream)\n",
      "                 ^^^^^^^^^^^^^^^^^^^^^^^^^^^^^^^^^^^^^^^\n",
      "  File \"C:\\Users\\wurfil\\AppData\\Local\\Programs\\Python\\Python311\\Lib\\site-packages\\pypdfium2\\_helpers\\document.py\", line 78, in __init__\n",
      "    self.raw, to_hold, to_close = _open_pdf(self._input, self._password, self._autoclose)\n",
      "                                  ^^^^^^^^^^^^^^^^^^^^^^^^^^^^^^^^^^^^^^^^^^^^^^^^^^^^^^^\n",
      "  File \"C:\\Users\\wurfil\\AppData\\Local\\Programs\\Python\\Python311\\Lib\\site-packages\\pypdfium2\\_helpers\\document.py\", line 678, in _open_pdf\n",
      "    raise PdfiumError(f\"Failed to load document (PDFium: {pdfium_i.ErrorToStr.get(err_code)}).\")\n",
      "pypdfium2._helpers.misc.PdfiumError: Failed to load document (PDFium: Data format error).\n",
      "ERROR:root:Ошибка при обработке .\\input\\4.pdf: Input document input\\4.pdf is not valid.\n",
      "ERROR:docling.datamodel.document:An unexpected error occurred while opening the document 45.pdf\n",
      "Traceback (most recent call last):\n",
      "  File \"C:\\Users\\wurfil\\AppData\\Local\\Programs\\Python\\Python311\\Lib\\site-packages\\docling\\datamodel\\document.py\", line 120, in __init__\n",
      "    self._init_doc(backend, path_or_stream)\n",
      "  File \"C:\\Users\\wurfil\\AppData\\Local\\Programs\\Python\\Python311\\Lib\\site-packages\\docling\\datamodel\\document.py\", line 173, in _init_doc\n",
      "    self._backend = backend(self, path_or_stream=path_or_stream)\n",
      "                    ^^^^^^^^^^^^^^^^^^^^^^^^^^^^^^^^^^^^^^^^^^^^\n",
      "  File \"C:\\Users\\wurfil\\AppData\\Local\\Programs\\Python\\Python311\\Lib\\site-packages\\docling\\backend\\docling_parse_backend.py\", line 194, in __init__\n",
      "    self._pdoc = pdfium.PdfDocument(self.path_or_stream)\n",
      "                 ^^^^^^^^^^^^^^^^^^^^^^^^^^^^^^^^^^^^^^^\n",
      "  File \"C:\\Users\\wurfil\\AppData\\Local\\Programs\\Python\\Python311\\Lib\\site-packages\\pypdfium2\\_helpers\\document.py\", line 78, in __init__\n",
      "    self.raw, to_hold, to_close = _open_pdf(self._input, self._password, self._autoclose)\n",
      "                                  ^^^^^^^^^^^^^^^^^^^^^^^^^^^^^^^^^^^^^^^^^^^^^^^^^^^^^^^\n",
      "  File \"C:\\Users\\wurfil\\AppData\\Local\\Programs\\Python\\Python311\\Lib\\site-packages\\pypdfium2\\_helpers\\document.py\", line 678, in _open_pdf\n",
      "    raise PdfiumError(f\"Failed to load document (PDFium: {pdfium_i.ErrorToStr.get(err_code)}).\")\n",
      "pypdfium2._helpers.misc.PdfiumError: Failed to load document (PDFium: Data format error).\n",
      "ERROR:root:Ошибка при обработке .\\input\\45.pdf: Input document input\\45.pdf is not valid.\n",
      "ERROR:docling.datamodel.document:An unexpected error occurred while opening the document 47.pdf\n",
      "Traceback (most recent call last):\n",
      "  File \"C:\\Users\\wurfil\\AppData\\Local\\Programs\\Python\\Python311\\Lib\\site-packages\\docling\\datamodel\\document.py\", line 120, in __init__\n",
      "    self._init_doc(backend, path_or_stream)\n",
      "  File \"C:\\Users\\wurfil\\AppData\\Local\\Programs\\Python\\Python311\\Lib\\site-packages\\docling\\datamodel\\document.py\", line 173, in _init_doc\n",
      "    self._backend = backend(self, path_or_stream=path_or_stream)\n",
      "                    ^^^^^^^^^^^^^^^^^^^^^^^^^^^^^^^^^^^^^^^^^^^^\n",
      "  File \"C:\\Users\\wurfil\\AppData\\Local\\Programs\\Python\\Python311\\Lib\\site-packages\\docling\\backend\\docling_parse_backend.py\", line 194, in __init__\n",
      "    self._pdoc = pdfium.PdfDocument(self.path_or_stream)\n",
      "                 ^^^^^^^^^^^^^^^^^^^^^^^^^^^^^^^^^^^^^^^\n",
      "  File \"C:\\Users\\wurfil\\AppData\\Local\\Programs\\Python\\Python311\\Lib\\site-packages\\pypdfium2\\_helpers\\document.py\", line 78, in __init__\n",
      "    self.raw, to_hold, to_close = _open_pdf(self._input, self._password, self._autoclose)\n",
      "                                  ^^^^^^^^^^^^^^^^^^^^^^^^^^^^^^^^^^^^^^^^^^^^^^^^^^^^^^^\n",
      "  File \"C:\\Users\\wurfil\\AppData\\Local\\Programs\\Python\\Python311\\Lib\\site-packages\\pypdfium2\\_helpers\\document.py\", line 678, in _open_pdf\n",
      "    raise PdfiumError(f\"Failed to load document (PDFium: {pdfium_i.ErrorToStr.get(err_code)}).\")\n",
      "pypdfium2._helpers.misc.PdfiumError: Failed to load document (PDFium: Data format error).\n",
      "ERROR:root:Ошибка при обработке .\\input\\47.pdf: Input document input\\47.pdf is not valid.\n",
      "ERROR:docling.datamodel.document:An unexpected error occurred while opening the document 48.pdf\n",
      "Traceback (most recent call last):\n",
      "  File \"C:\\Users\\wurfil\\AppData\\Local\\Programs\\Python\\Python311\\Lib\\site-packages\\docling\\datamodel\\document.py\", line 120, in __init__\n",
      "    self._init_doc(backend, path_or_stream)\n",
      "  File \"C:\\Users\\wurfil\\AppData\\Local\\Programs\\Python\\Python311\\Lib\\site-packages\\docling\\datamodel\\document.py\", line 173, in _init_doc\n",
      "    self._backend = backend(self, path_or_stream=path_or_stream)\n",
      "                    ^^^^^^^^^^^^^^^^^^^^^^^^^^^^^^^^^^^^^^^^^^^^\n",
      "  File \"C:\\Users\\wurfil\\AppData\\Local\\Programs\\Python\\Python311\\Lib\\site-packages\\docling\\backend\\docling_parse_backend.py\", line 194, in __init__\n",
      "    self._pdoc = pdfium.PdfDocument(self.path_or_stream)\n",
      "                 ^^^^^^^^^^^^^^^^^^^^^^^^^^^^^^^^^^^^^^^\n",
      "  File \"C:\\Users\\wurfil\\AppData\\Local\\Programs\\Python\\Python311\\Lib\\site-packages\\pypdfium2\\_helpers\\document.py\", line 78, in __init__\n",
      "    self.raw, to_hold, to_close = _open_pdf(self._input, self._password, self._autoclose)\n",
      "                                  ^^^^^^^^^^^^^^^^^^^^^^^^^^^^^^^^^^^^^^^^^^^^^^^^^^^^^^^\n",
      "  File \"C:\\Users\\wurfil\\AppData\\Local\\Programs\\Python\\Python311\\Lib\\site-packages\\pypdfium2\\_helpers\\document.py\", line 678, in _open_pdf\n",
      "    raise PdfiumError(f\"Failed to load document (PDFium: {pdfium_i.ErrorToStr.get(err_code)}).\")\n",
      "pypdfium2._helpers.misc.PdfiumError: Failed to load document (PDFium: Data format error).\n",
      "ERROR:root:Ошибка при обработке .\\input\\48.pdf: Input document input\\48.pdf is not valid.\n",
      "ERROR:docling.datamodel.document:An unexpected error occurred while opening the document 29.pdf\n",
      "Traceback (most recent call last):\n",
      "  File \"C:\\Users\\wurfil\\AppData\\Local\\Programs\\Python\\Python311\\Lib\\site-packages\\docling\\datamodel\\document.py\", line 120, in __init__\n",
      "    self._init_doc(backend, path_or_stream)\n",
      "  File \"C:\\Users\\wurfil\\AppData\\Local\\Programs\\Python\\Python311\\Lib\\site-packages\\docling\\datamodel\\document.py\", line 173, in _init_doc\n",
      "    self._backend = backend(self, path_or_stream=path_or_stream)\n",
      "                    ^^^^^^^^^^^^^^^^^^^^^^^^^^^^^^^^^^^^^^^^^^^^\n",
      "  File \"C:\\Users\\wurfil\\AppData\\Local\\Programs\\Python\\Python311\\Lib\\site-packages\\docling\\backend\\docling_parse_backend.py\", line 194, in __init__\n",
      "    self._pdoc = pdfium.PdfDocument(self.path_or_stream)\n",
      "                 ^^^^^^^^^^^^^^^^^^^^^^^^^^^^^^^^^^^^^^^\n",
      "  File \"C:\\Users\\wurfil\\AppData\\Local\\Programs\\Python\\Python311\\Lib\\site-packages\\pypdfium2\\_helpers\\document.py\", line 78, in __init__\n",
      "    self.raw, to_hold, to_close = _open_pdf(self._input, self._password, self._autoclose)\n",
      "                                  ^^^^^^^^^^^^^^^^^^^^^^^^^^^^^^^^^^^^^^^^^^^^^^^^^^^^^^^\n",
      "  File \"C:\\Users\\wurfil\\AppData\\Local\\Programs\\Python\\Python311\\Lib\\site-packages\\pypdfium2\\_helpers\\document.py\", line 678, in _open_pdf\n",
      "    raise PdfiumError(f\"Failed to load document (PDFium: {pdfium_i.ErrorToStr.get(err_code)}).\")\n",
      "pypdfium2._helpers.misc.PdfiumError: Failed to load document (PDFium: Data format error).\n",
      "ERROR:root:Ошибка при обработке .\\input\\29.pdf: Input document input\\29.pdf is not valid.\n",
      "ERROR:docling.datamodel.document:An unexpected error occurred while opening the document 40.pdf\n",
      "Traceback (most recent call last):\n",
      "  File \"C:\\Users\\wurfil\\AppData\\Local\\Programs\\Python\\Python311\\Lib\\site-packages\\docling\\datamodel\\document.py\", line 120, in __init__\n",
      "    self._init_doc(backend, path_or_stream)\n",
      "  File \"C:\\Users\\wurfil\\AppData\\Local\\Programs\\Python\\Python311\\Lib\\site-packages\\docling\\datamodel\\document.py\", line 173, in _init_doc\n",
      "    self._backend = backend(self, path_or_stream=path_or_stream)\n",
      "                    ^^^^^^^^^^^^^^^^^^^^^^^^^^^^^^^^^^^^^^^^^^^^\n",
      "  File \"C:\\Users\\wurfil\\AppData\\Local\\Programs\\Python\\Python311\\Lib\\site-packages\\docling\\backend\\docling_parse_backend.py\", line 194, in __init__\n",
      "    self._pdoc = pdfium.PdfDocument(self.path_or_stream)\n",
      "                 ^^^^^^^^^^^^^^^^^^^^^^^^^^^^^^^^^^^^^^^\n",
      "  File \"C:\\Users\\wurfil\\AppData\\Local\\Programs\\Python\\Python311\\Lib\\site-packages\\pypdfium2\\_helpers\\document.py\", line 78, in __init__\n",
      "    self.raw, to_hold, to_close = _open_pdf(self._input, self._password, self._autoclose)\n",
      "                                  ^^^^^^^^^^^^^^^^^^^^^^^^^^^^^^^^^^^^^^^^^^^^^^^^^^^^^^^\n",
      "  File \"C:\\Users\\wurfil\\AppData\\Local\\Programs\\Python\\Python311\\Lib\\site-packages\\pypdfium2\\_helpers\\document.py\", line 678, in _open_pdf\n",
      "    raise PdfiumError(f\"Failed to load document (PDFium: {pdfium_i.ErrorToStr.get(err_code)}).\")\n",
      "pypdfium2._helpers.misc.PdfiumError: Failed to load document (PDFium: Data format error).\n",
      "ERROR:root:Ошибка при обработке .\\input\\40.pdf: Input document input\\40.pdf is not valid.\n",
      "ERROR:docling.datamodel.document:An unexpected error occurred while opening the document 5.pdf\n",
      "Traceback (most recent call last):\n",
      "  File \"C:\\Users\\wurfil\\AppData\\Local\\Programs\\Python\\Python311\\Lib\\site-packages\\docling\\datamodel\\document.py\", line 120, in __init__\n",
      "    self._init_doc(backend, path_or_stream)\n",
      "  File \"C:\\Users\\wurfil\\AppData\\Local\\Programs\\Python\\Python311\\Lib\\site-packages\\docling\\datamodel\\document.py\", line 173, in _init_doc\n",
      "    self._backend = backend(self, path_or_stream=path_or_stream)\n",
      "                    ^^^^^^^^^^^^^^^^^^^^^^^^^^^^^^^^^^^^^^^^^^^^\n",
      "  File \"C:\\Users\\wurfil\\AppData\\Local\\Programs\\Python\\Python311\\Lib\\site-packages\\docling\\backend\\docling_parse_backend.py\", line 194, in __init__\n",
      "    self._pdoc = pdfium.PdfDocument(self.path_or_stream)\n",
      "                 ^^^^^^^^^^^^^^^^^^^^^^^^^^^^^^^^^^^^^^^\n",
      "  File \"C:\\Users\\wurfil\\AppData\\Local\\Programs\\Python\\Python311\\Lib\\site-packages\\pypdfium2\\_helpers\\document.py\", line 78, in __init__\n",
      "    self.raw, to_hold, to_close = _open_pdf(self._input, self._password, self._autoclose)\n",
      "                                  ^^^^^^^^^^^^^^^^^^^^^^^^^^^^^^^^^^^^^^^^^^^^^^^^^^^^^^^\n",
      "  File \"C:\\Users\\wurfil\\AppData\\Local\\Programs\\Python\\Python311\\Lib\\site-packages\\pypdfium2\\_helpers\\document.py\", line 678, in _open_pdf\n",
      "    raise PdfiumError(f\"Failed to load document (PDFium: {pdfium_i.ErrorToStr.get(err_code)}).\")\n",
      "pypdfium2._helpers.misc.PdfiumError: Failed to load document (PDFium: Data format error).\n",
      "ERROR:root:Ошибка при обработке .\\input\\5.pdf: Input document input\\5.pdf is not valid.\n",
      "ERROR:docling.datamodel.document:An unexpected error occurred while opening the document 50.pdf\n",
      "Traceback (most recent call last):\n",
      "  File \"C:\\Users\\wurfil\\AppData\\Local\\Programs\\Python\\Python311\\Lib\\site-packages\\docling\\datamodel\\document.py\", line 120, in __init__\n",
      "    self._init_doc(backend, path_or_stream)\n",
      "  File \"C:\\Users\\wurfil\\AppData\\Local\\Programs\\Python\\Python311\\Lib\\site-packages\\docling\\datamodel\\document.py\", line 173, in _init_doc\n",
      "    self._backend = backend(self, path_or_stream=path_or_stream)\n",
      "                    ^^^^^^^^^^^^^^^^^^^^^^^^^^^^^^^^^^^^^^^^^^^^\n",
      "  File \"C:\\Users\\wurfil\\AppData\\Local\\Programs\\Python\\Python311\\Lib\\site-packages\\docling\\backend\\docling_parse_backend.py\", line 194, in __init__\n",
      "    self._pdoc = pdfium.PdfDocument(self.path_or_stream)\n",
      "                 ^^^^^^^^^^^^^^^^^^^^^^^^^^^^^^^^^^^^^^^\n",
      "  File \"C:\\Users\\wurfil\\AppData\\Local\\Programs\\Python\\Python311\\Lib\\site-packages\\pypdfium2\\_helpers\\document.py\", line 78, in __init__\n",
      "    self.raw, to_hold, to_close = _open_pdf(self._input, self._password, self._autoclose)\n",
      "                                  ^^^^^^^^^^^^^^^^^^^^^^^^^^^^^^^^^^^^^^^^^^^^^^^^^^^^^^^\n",
      "  File \"C:\\Users\\wurfil\\AppData\\Local\\Programs\\Python\\Python311\\Lib\\site-packages\\pypdfium2\\_helpers\\document.py\", line 678, in _open_pdf\n",
      "    raise PdfiumError(f\"Failed to load document (PDFium: {pdfium_i.ErrorToStr.get(err_code)}).\")\n",
      "pypdfium2._helpers.misc.PdfiumError: Failed to load document (PDFium: Data format error).\n",
      "ERROR:root:Ошибка при обработке .\\input\\50.pdf: Input document input\\50.pdf is not valid.\n",
      "ERROR:docling.datamodel.document:An unexpected error occurred while opening the document 51.pdf\n",
      "Traceback (most recent call last):\n",
      "  File \"C:\\Users\\wurfil\\AppData\\Local\\Programs\\Python\\Python311\\Lib\\site-packages\\docling\\datamodel\\document.py\", line 120, in __init__\n",
      "    self._init_doc(backend, path_or_stream)\n",
      "  File \"C:\\Users\\wurfil\\AppData\\Local\\Programs\\Python\\Python311\\Lib\\site-packages\\docling\\datamodel\\document.py\", line 173, in _init_doc\n",
      "    self._backend = backend(self, path_or_stream=path_or_stream)\n",
      "                    ^^^^^^^^^^^^^^^^^^^^^^^^^^^^^^^^^^^^^^^^^^^^\n",
      "  File \"C:\\Users\\wurfil\\AppData\\Local\\Programs\\Python\\Python311\\Lib\\site-packages\\docling\\backend\\docling_parse_backend.py\", line 194, in __init__\n",
      "    self._pdoc = pdfium.PdfDocument(self.path_or_stream)\n",
      "                 ^^^^^^^^^^^^^^^^^^^^^^^^^^^^^^^^^^^^^^^\n",
      "  File \"C:\\Users\\wurfil\\AppData\\Local\\Programs\\Python\\Python311\\Lib\\site-packages\\pypdfium2\\_helpers\\document.py\", line 78, in __init__\n",
      "    self.raw, to_hold, to_close = _open_pdf(self._input, self._password, self._autoclose)\n",
      "                                  ^^^^^^^^^^^^^^^^^^^^^^^^^^^^^^^^^^^^^^^^^^^^^^^^^^^^^^^\n",
      "  File \"C:\\Users\\wurfil\\AppData\\Local\\Programs\\Python\\Python311\\Lib\\site-packages\\pypdfium2\\_helpers\\document.py\", line 678, in _open_pdf\n",
      "    raise PdfiumError(f\"Failed to load document (PDFium: {pdfium_i.ErrorToStr.get(err_code)}).\")\n",
      "pypdfium2._helpers.misc.PdfiumError: Failed to load document (PDFium: Data format error).\n",
      "ERROR:root:Ошибка при обработке .\\input\\51.pdf: Input document input\\51.pdf is not valid.\n",
      "ERROR:docling.datamodel.document:An unexpected error occurred while opening the document 49.pdf\n",
      "Traceback (most recent call last):\n",
      "  File \"C:\\Users\\wurfil\\AppData\\Local\\Programs\\Python\\Python311\\Lib\\site-packages\\docling\\datamodel\\document.py\", line 120, in __init__\n",
      "    self._init_doc(backend, path_or_stream)\n",
      "  File \"C:\\Users\\wurfil\\AppData\\Local\\Programs\\Python\\Python311\\Lib\\site-packages\\docling\\datamodel\\document.py\", line 173, in _init_doc\n",
      "    self._backend = backend(self, path_or_stream=path_or_stream)\n",
      "                    ^^^^^^^^^^^^^^^^^^^^^^^^^^^^^^^^^^^^^^^^^^^^\n",
      "  File \"C:\\Users\\wurfil\\AppData\\Local\\Programs\\Python\\Python311\\Lib\\site-packages\\docling\\backend\\docling_parse_backend.py\", line 194, in __init__\n",
      "    self._pdoc = pdfium.PdfDocument(self.path_or_stream)\n",
      "                 ^^^^^^^^^^^^^^^^^^^^^^^^^^^^^^^^^^^^^^^\n",
      "  File \"C:\\Users\\wurfil\\AppData\\Local\\Programs\\Python\\Python311\\Lib\\site-packages\\pypdfium2\\_helpers\\document.py\", line 78, in __init__\n",
      "    self.raw, to_hold, to_close = _open_pdf(self._input, self._password, self._autoclose)\n",
      "                                  ^^^^^^^^^^^^^^^^^^^^^^^^^^^^^^^^^^^^^^^^^^^^^^^^^^^^^^^\n",
      "  File \"C:\\Users\\wurfil\\AppData\\Local\\Programs\\Python\\Python311\\Lib\\site-packages\\pypdfium2\\_helpers\\document.py\", line 678, in _open_pdf\n",
      "    raise PdfiumError(f\"Failed to load document (PDFium: {pdfium_i.ErrorToStr.get(err_code)}).\")\n",
      "pypdfium2._helpers.misc.PdfiumError: Failed to load document (PDFium: Data format error).\n",
      "ERROR:root:Ошибка при обработке .\\input\\49.pdf: Input document input\\49.pdf is not valid.\n",
      "ERROR:docling.datamodel.document:An unexpected error occurred while opening the document 54.pdf\n",
      "Traceback (most recent call last):\n",
      "  File \"C:\\Users\\wurfil\\AppData\\Local\\Programs\\Python\\Python311\\Lib\\site-packages\\docling\\datamodel\\document.py\", line 120, in __init__\n",
      "    self._init_doc(backend, path_or_stream)\n",
      "  File \"C:\\Users\\wurfil\\AppData\\Local\\Programs\\Python\\Python311\\Lib\\site-packages\\docling\\datamodel\\document.py\", line 173, in _init_doc\n",
      "    self._backend = backend(self, path_or_stream=path_or_stream)\n",
      "                    ^^^^^^^^^^^^^^^^^^^^^^^^^^^^^^^^^^^^^^^^^^^^\n",
      "  File \"C:\\Users\\wurfil\\AppData\\Local\\Programs\\Python\\Python311\\Lib\\site-packages\\docling\\backend\\docling_parse_backend.py\", line 194, in __init__\n",
      "    self._pdoc = pdfium.PdfDocument(self.path_or_stream)\n",
      "                 ^^^^^^^^^^^^^^^^^^^^^^^^^^^^^^^^^^^^^^^\n",
      "  File \"C:\\Users\\wurfil\\AppData\\Local\\Programs\\Python\\Python311\\Lib\\site-packages\\pypdfium2\\_helpers\\document.py\", line 78, in __init__\n",
      "    self.raw, to_hold, to_close = _open_pdf(self._input, self._password, self._autoclose)\n",
      "                                  ^^^^^^^^^^^^^^^^^^^^^^^^^^^^^^^^^^^^^^^^^^^^^^^^^^^^^^^\n",
      "  File \"C:\\Users\\wurfil\\AppData\\Local\\Programs\\Python\\Python311\\Lib\\site-packages\\pypdfium2\\_helpers\\document.py\", line 678, in _open_pdf\n",
      "    raise PdfiumError(f\"Failed to load document (PDFium: {pdfium_i.ErrorToStr.get(err_code)}).\")\n",
      "pypdfium2._helpers.misc.PdfiumError: Failed to load document (PDFium: Data format error).\n",
      "ERROR:root:Ошибка при обработке .\\input\\54.pdf: Input document input\\54.pdf is not valid.\n",
      "ERROR:docling.datamodel.document:An unexpected error occurred while opening the document 55.pdf\n",
      "Traceback (most recent call last):\n",
      "  File \"C:\\Users\\wurfil\\AppData\\Local\\Programs\\Python\\Python311\\Lib\\site-packages\\docling\\datamodel\\document.py\", line 120, in __init__\n",
      "    self._init_doc(backend, path_or_stream)\n",
      "  File \"C:\\Users\\wurfil\\AppData\\Local\\Programs\\Python\\Python311\\Lib\\site-packages\\docling\\datamodel\\document.py\", line 173, in _init_doc\n",
      "    self._backend = backend(self, path_or_stream=path_or_stream)\n",
      "                    ^^^^^^^^^^^^^^^^^^^^^^^^^^^^^^^^^^^^^^^^^^^^\n",
      "  File \"C:\\Users\\wurfil\\AppData\\Local\\Programs\\Python\\Python311\\Lib\\site-packages\\docling\\backend\\docling_parse_backend.py\", line 194, in __init__\n",
      "    self._pdoc = pdfium.PdfDocument(self.path_or_stream)\n",
      "                 ^^^^^^^^^^^^^^^^^^^^^^^^^^^^^^^^^^^^^^^\n",
      "  File \"C:\\Users\\wurfil\\AppData\\Local\\Programs\\Python\\Python311\\Lib\\site-packages\\pypdfium2\\_helpers\\document.py\", line 78, in __init__\n",
      "    self.raw, to_hold, to_close = _open_pdf(self._input, self._password, self._autoclose)\n",
      "                                  ^^^^^^^^^^^^^^^^^^^^^^^^^^^^^^^^^^^^^^^^^^^^^^^^^^^^^^^\n",
      "  File \"C:\\Users\\wurfil\\AppData\\Local\\Programs\\Python\\Python311\\Lib\\site-packages\\pypdfium2\\_helpers\\document.py\", line 678, in _open_pdf\n",
      "    raise PdfiumError(f\"Failed to load document (PDFium: {pdfium_i.ErrorToStr.get(err_code)}).\")\n",
      "pypdfium2._helpers.misc.PdfiumError: Failed to load document (PDFium: Data format error).\n",
      "ERROR:root:Ошибка при обработке .\\input\\55.pdf: Input document input\\55.pdf is not valid.\n",
      "ERROR:docling.datamodel.document:An unexpected error occurred while opening the document 52.pdf\n",
      "Traceback (most recent call last):\n",
      "  File \"C:\\Users\\wurfil\\AppData\\Local\\Programs\\Python\\Python311\\Lib\\site-packages\\docling\\datamodel\\document.py\", line 120, in __init__\n",
      "    self._init_doc(backend, path_or_stream)\n",
      "  File \"C:\\Users\\wurfil\\AppData\\Local\\Programs\\Python\\Python311\\Lib\\site-packages\\docling\\datamodel\\document.py\", line 173, in _init_doc\n",
      "    self._backend = backend(self, path_or_stream=path_or_stream)\n",
      "                    ^^^^^^^^^^^^^^^^^^^^^^^^^^^^^^^^^^^^^^^^^^^^\n",
      "  File \"C:\\Users\\wurfil\\AppData\\Local\\Programs\\Python\\Python311\\Lib\\site-packages\\docling\\backend\\docling_parse_backend.py\", line 194, in __init__\n",
      "    self._pdoc = pdfium.PdfDocument(self.path_or_stream)\n",
      "                 ^^^^^^^^^^^^^^^^^^^^^^^^^^^^^^^^^^^^^^^\n",
      "  File \"C:\\Users\\wurfil\\AppData\\Local\\Programs\\Python\\Python311\\Lib\\site-packages\\pypdfium2\\_helpers\\document.py\", line 78, in __init__\n",
      "    self.raw, to_hold, to_close = _open_pdf(self._input, self._password, self._autoclose)\n",
      "                                  ^^^^^^^^^^^^^^^^^^^^^^^^^^^^^^^^^^^^^^^^^^^^^^^^^^^^^^^\n",
      "  File \"C:\\Users\\wurfil\\AppData\\Local\\Programs\\Python\\Python311\\Lib\\site-packages\\pypdfium2\\_helpers\\document.py\", line 678, in _open_pdf\n",
      "    raise PdfiumError(f\"Failed to load document (PDFium: {pdfium_i.ErrorToStr.get(err_code)}).\")\n",
      "pypdfium2._helpers.misc.PdfiumError: Failed to load document (PDFium: Data format error).\n",
      "ERROR:root:Ошибка при обработке .\\input\\52.pdf: Input document input\\52.pdf is not valid.\n",
      "ERROR:docling.datamodel.document:An unexpected error occurred while opening the document 56.pdf\n",
      "Traceback (most recent call last):\n",
      "  File \"C:\\Users\\wurfil\\AppData\\Local\\Programs\\Python\\Python311\\Lib\\site-packages\\docling\\datamodel\\document.py\", line 120, in __init__\n",
      "    self._init_doc(backend, path_or_stream)\n",
      "  File \"C:\\Users\\wurfil\\AppData\\Local\\Programs\\Python\\Python311\\Lib\\site-packages\\docling\\datamodel\\document.py\", line 173, in _init_doc\n",
      "    self._backend = backend(self, path_or_stream=path_or_stream)\n",
      "                    ^^^^^^^^^^^^^^^^^^^^^^^^^^^^^^^^^^^^^^^^^^^^\n",
      "  File \"C:\\Users\\wurfil\\AppData\\Local\\Programs\\Python\\Python311\\Lib\\site-packages\\docling\\backend\\docling_parse_backend.py\", line 194, in __init__\n",
      "    self._pdoc = pdfium.PdfDocument(self.path_or_stream)\n",
      "                 ^^^^^^^^^^^^^^^^^^^^^^^^^^^^^^^^^^^^^^^\n",
      "  File \"C:\\Users\\wurfil\\AppData\\Local\\Programs\\Python\\Python311\\Lib\\site-packages\\pypdfium2\\_helpers\\document.py\", line 78, in __init__\n",
      "    self.raw, to_hold, to_close = _open_pdf(self._input, self._password, self._autoclose)\n",
      "                                  ^^^^^^^^^^^^^^^^^^^^^^^^^^^^^^^^^^^^^^^^^^^^^^^^^^^^^^^\n",
      "  File \"C:\\Users\\wurfil\\AppData\\Local\\Programs\\Python\\Python311\\Lib\\site-packages\\pypdfium2\\_helpers\\document.py\", line 678, in _open_pdf\n",
      "    raise PdfiumError(f\"Failed to load document (PDFium: {pdfium_i.ErrorToStr.get(err_code)}).\")\n",
      "pypdfium2._helpers.misc.PdfiumError: Failed to load document (PDFium: Data format error).\n",
      "ERROR:root:Ошибка при обработке .\\input\\56.pdf: Input document input\\56.pdf is not valid.\n",
      "ERROR:docling.datamodel.document:An unexpected error occurred while opening the document 57.pdf\n",
      "Traceback (most recent call last):\n",
      "  File \"C:\\Users\\wurfil\\AppData\\Local\\Programs\\Python\\Python311\\Lib\\site-packages\\docling\\datamodel\\document.py\", line 120, in __init__\n",
      "    self._init_doc(backend, path_or_stream)\n",
      "  File \"C:\\Users\\wurfil\\AppData\\Local\\Programs\\Python\\Python311\\Lib\\site-packages\\docling\\datamodel\\document.py\", line 173, in _init_doc\n",
      "    self._backend = backend(self, path_or_stream=path_or_stream)\n",
      "                    ^^^^^^^^^^^^^^^^^^^^^^^^^^^^^^^^^^^^^^^^^^^^\n",
      "  File \"C:\\Users\\wurfil\\AppData\\Local\\Programs\\Python\\Python311\\Lib\\site-packages\\docling\\backend\\docling_parse_backend.py\", line 194, in __init__\n",
      "    self._pdoc = pdfium.PdfDocument(self.path_or_stream)\n",
      "                 ^^^^^^^^^^^^^^^^^^^^^^^^^^^^^^^^^^^^^^^\n",
      "  File \"C:\\Users\\wurfil\\AppData\\Local\\Programs\\Python\\Python311\\Lib\\site-packages\\pypdfium2\\_helpers\\document.py\", line 78, in __init__\n",
      "    self.raw, to_hold, to_close = _open_pdf(self._input, self._password, self._autoclose)\n",
      "                                  ^^^^^^^^^^^^^^^^^^^^^^^^^^^^^^^^^^^^^^^^^^^^^^^^^^^^^^^\n",
      "  File \"C:\\Users\\wurfil\\AppData\\Local\\Programs\\Python\\Python311\\Lib\\site-packages\\pypdfium2\\_helpers\\document.py\", line 678, in _open_pdf\n",
      "    raise PdfiumError(f\"Failed to load document (PDFium: {pdfium_i.ErrorToStr.get(err_code)}).\")\n",
      "pypdfium2._helpers.misc.PdfiumError: Failed to load document (PDFium: Data format error).\n",
      "ERROR:root:Ошибка при обработке .\\input\\57.pdf: Input document input\\57.pdf is not valid.\n",
      "ERROR:docling.datamodel.document:An unexpected error occurred while opening the document 58.pdf\n",
      "Traceback (most recent call last):\n",
      "  File \"C:\\Users\\wurfil\\AppData\\Local\\Programs\\Python\\Python311\\Lib\\site-packages\\docling\\datamodel\\document.py\", line 120, in __init__\n",
      "    self._init_doc(backend, path_or_stream)\n",
      "  File \"C:\\Users\\wurfil\\AppData\\Local\\Programs\\Python\\Python311\\Lib\\site-packages\\docling\\datamodel\\document.py\", line 173, in _init_doc\n",
      "    self._backend = backend(self, path_or_stream=path_or_stream)\n",
      "                    ^^^^^^^^^^^^^^^^^^^^^^^^^^^^^^^^^^^^^^^^^^^^\n",
      "  File \"C:\\Users\\wurfil\\AppData\\Local\\Programs\\Python\\Python311\\Lib\\site-packages\\docling\\backend\\docling_parse_backend.py\", line 194, in __init__\n",
      "    self._pdoc = pdfium.PdfDocument(self.path_or_stream)\n",
      "                 ^^^^^^^^^^^^^^^^^^^^^^^^^^^^^^^^^^^^^^^\n",
      "  File \"C:\\Users\\wurfil\\AppData\\Local\\Programs\\Python\\Python311\\Lib\\site-packages\\pypdfium2\\_helpers\\document.py\", line 78, in __init__\n",
      "    self.raw, to_hold, to_close = _open_pdf(self._input, self._password, self._autoclose)\n",
      "                                  ^^^^^^^^^^^^^^^^^^^^^^^^^^^^^^^^^^^^^^^^^^^^^^^^^^^^^^^\n",
      "  File \"C:\\Users\\wurfil\\AppData\\Local\\Programs\\Python\\Python311\\Lib\\site-packages\\pypdfium2\\_helpers\\document.py\", line 678, in _open_pdf\n",
      "    raise PdfiumError(f\"Failed to load document (PDFium: {pdfium_i.ErrorToStr.get(err_code)}).\")\n",
      "pypdfium2._helpers.misc.PdfiumError: Failed to load document (PDFium: Data format error).\n",
      "ERROR:root:Ошибка при обработке .\\input\\58.pdf: Input document input\\58.pdf is not valid.\n",
      "ERROR:docling.datamodel.document:An unexpected error occurred while opening the document 53.pdf\n",
      "Traceback (most recent call last):\n",
      "  File \"C:\\Users\\wurfil\\AppData\\Local\\Programs\\Python\\Python311\\Lib\\site-packages\\docling\\datamodel\\document.py\", line 120, in __init__\n",
      "    self._init_doc(backend, path_or_stream)\n",
      "  File \"C:\\Users\\wurfil\\AppData\\Local\\Programs\\Python\\Python311\\Lib\\site-packages\\docling\\datamodel\\document.py\", line 173, in _init_doc\n",
      "    self._backend = backend(self, path_or_stream=path_or_stream)\n",
      "                    ^^^^^^^^^^^^^^^^^^^^^^^^^^^^^^^^^^^^^^^^^^^^\n",
      "  File \"C:\\Users\\wurfil\\AppData\\Local\\Programs\\Python\\Python311\\Lib\\site-packages\\docling\\backend\\docling_parse_backend.py\", line 194, in __init__\n",
      "    self._pdoc = pdfium.PdfDocument(self.path_or_stream)\n",
      "                 ^^^^^^^^^^^^^^^^^^^^^^^^^^^^^^^^^^^^^^^\n",
      "  File \"C:\\Users\\wurfil\\AppData\\Local\\Programs\\Python\\Python311\\Lib\\site-packages\\pypdfium2\\_helpers\\document.py\", line 78, in __init__\n",
      "    self.raw, to_hold, to_close = _open_pdf(self._input, self._password, self._autoclose)\n",
      "                                  ^^^^^^^^^^^^^^^^^^^^^^^^^^^^^^^^^^^^^^^^^^^^^^^^^^^^^^^\n",
      "  File \"C:\\Users\\wurfil\\AppData\\Local\\Programs\\Python\\Python311\\Lib\\site-packages\\pypdfium2\\_helpers\\document.py\", line 678, in _open_pdf\n",
      "    raise PdfiumError(f\"Failed to load document (PDFium: {pdfium_i.ErrorToStr.get(err_code)}).\")\n",
      "pypdfium2._helpers.misc.PdfiumError: Failed to load document (PDFium: Data format error).\n",
      "ERROR:root:Ошибка при обработке .\\input\\53.pdf: Input document input\\53.pdf is not valid.\n",
      "ERROR:docling.datamodel.document:An unexpected error occurred while opening the document 60.pdf\n",
      "Traceback (most recent call last):\n",
      "  File \"C:\\Users\\wurfil\\AppData\\Local\\Programs\\Python\\Python311\\Lib\\site-packages\\docling\\datamodel\\document.py\", line 120, in __init__\n",
      "    self._init_doc(backend, path_or_stream)\n",
      "  File \"C:\\Users\\wurfil\\AppData\\Local\\Programs\\Python\\Python311\\Lib\\site-packages\\docling\\datamodel\\document.py\", line 173, in _init_doc\n",
      "    self._backend = backend(self, path_or_stream=path_or_stream)\n",
      "                    ^^^^^^^^^^^^^^^^^^^^^^^^^^^^^^^^^^^^^^^^^^^^\n",
      "  File \"C:\\Users\\wurfil\\AppData\\Local\\Programs\\Python\\Python311\\Lib\\site-packages\\docling\\backend\\docling_parse_backend.py\", line 194, in __init__\n",
      "    self._pdoc = pdfium.PdfDocument(self.path_or_stream)\n",
      "                 ^^^^^^^^^^^^^^^^^^^^^^^^^^^^^^^^^^^^^^^\n",
      "  File \"C:\\Users\\wurfil\\AppData\\Local\\Programs\\Python\\Python311\\Lib\\site-packages\\pypdfium2\\_helpers\\document.py\", line 78, in __init__\n",
      "    self.raw, to_hold, to_close = _open_pdf(self._input, self._password, self._autoclose)\n",
      "                                  ^^^^^^^^^^^^^^^^^^^^^^^^^^^^^^^^^^^^^^^^^^^^^^^^^^^^^^^\n",
      "  File \"C:\\Users\\wurfil\\AppData\\Local\\Programs\\Python\\Python311\\Lib\\site-packages\\pypdfium2\\_helpers\\document.py\", line 678, in _open_pdf\n",
      "    raise PdfiumError(f\"Failed to load document (PDFium: {pdfium_i.ErrorToStr.get(err_code)}).\")\n",
      "pypdfium2._helpers.misc.PdfiumError: Failed to load document (PDFium: Data format error).\n",
      "ERROR:root:Ошибка при обработке .\\input\\60.pdf: Input document input\\60.pdf is not valid.\n",
      "ERROR:docling.datamodel.document:An unexpected error occurred while opening the document 6.pdf\n",
      "Traceback (most recent call last):\n",
      "  File \"C:\\Users\\wurfil\\AppData\\Local\\Programs\\Python\\Python311\\Lib\\site-packages\\docling\\datamodel\\document.py\", line 120, in __init__\n",
      "    self._init_doc(backend, path_or_stream)\n",
      "  File \"C:\\Users\\wurfil\\AppData\\Local\\Programs\\Python\\Python311\\Lib\\site-packages\\docling\\datamodel\\document.py\", line 173, in _init_doc\n",
      "    self._backend = backend(self, path_or_stream=path_or_stream)\n",
      "                    ^^^^^^^^^^^^^^^^^^^^^^^^^^^^^^^^^^^^^^^^^^^^\n",
      "  File \"C:\\Users\\wurfil\\AppData\\Local\\Programs\\Python\\Python311\\Lib\\site-packages\\docling\\backend\\docling_parse_backend.py\", line 194, in __init__\n",
      "    self._pdoc = pdfium.PdfDocument(self.path_or_stream)\n",
      "                 ^^^^^^^^^^^^^^^^^^^^^^^^^^^^^^^^^^^^^^^\n",
      "  File \"C:\\Users\\wurfil\\AppData\\Local\\Programs\\Python\\Python311\\Lib\\site-packages\\pypdfium2\\_helpers\\document.py\", line 78, in __init__\n",
      "    self.raw, to_hold, to_close = _open_pdf(self._input, self._password, self._autoclose)\n",
      "                                  ^^^^^^^^^^^^^^^^^^^^^^^^^^^^^^^^^^^^^^^^^^^^^^^^^^^^^^^\n",
      "  File \"C:\\Users\\wurfil\\AppData\\Local\\Programs\\Python\\Python311\\Lib\\site-packages\\pypdfium2\\_helpers\\document.py\", line 678, in _open_pdf\n",
      "    raise PdfiumError(f\"Failed to load document (PDFium: {pdfium_i.ErrorToStr.get(err_code)}).\")\n",
      "pypdfium2._helpers.misc.PdfiumError: Failed to load document (PDFium: Data format error).\n",
      "ERROR:root:Ошибка при обработке .\\input\\6.pdf: Input document input\\6.pdf is not valid.\n",
      "ERROR:docling.datamodel.document:An unexpected error occurred while opening the document 61.pdf\n",
      "Traceback (most recent call last):\n",
      "  File \"C:\\Users\\wurfil\\AppData\\Local\\Programs\\Python\\Python311\\Lib\\site-packages\\docling\\datamodel\\document.py\", line 120, in __init__\n",
      "    self._init_doc(backend, path_or_stream)\n",
      "  File \"C:\\Users\\wurfil\\AppData\\Local\\Programs\\Python\\Python311\\Lib\\site-packages\\docling\\datamodel\\document.py\", line 173, in _init_doc\n",
      "    self._backend = backend(self, path_or_stream=path_or_stream)\n",
      "                    ^^^^^^^^^^^^^^^^^^^^^^^^^^^^^^^^^^^^^^^^^^^^\n",
      "  File \"C:\\Users\\wurfil\\AppData\\Local\\Programs\\Python\\Python311\\Lib\\site-packages\\docling\\backend\\docling_parse_backend.py\", line 194, in __init__\n",
      "    self._pdoc = pdfium.PdfDocument(self.path_or_stream)\n",
      "                 ^^^^^^^^^^^^^^^^^^^^^^^^^^^^^^^^^^^^^^^\n",
      "  File \"C:\\Users\\wurfil\\AppData\\Local\\Programs\\Python\\Python311\\Lib\\site-packages\\pypdfium2\\_helpers\\document.py\", line 78, in __init__\n",
      "    self.raw, to_hold, to_close = _open_pdf(self._input, self._password, self._autoclose)\n",
      "                                  ^^^^^^^^^^^^^^^^^^^^^^^^^^^^^^^^^^^^^^^^^^^^^^^^^^^^^^^\n",
      "  File \"C:\\Users\\wurfil\\AppData\\Local\\Programs\\Python\\Python311\\Lib\\site-packages\\pypdfium2\\_helpers\\document.py\", line 678, in _open_pdf\n",
      "    raise PdfiumError(f\"Failed to load document (PDFium: {pdfium_i.ErrorToStr.get(err_code)}).\")\n",
      "pypdfium2._helpers.misc.PdfiumError: Failed to load document (PDFium: Data format error).\n",
      "ERROR:root:Ошибка при обработке .\\input\\61.pdf: Input document input\\61.pdf is not valid.\n",
      "ERROR:docling.datamodel.document:An unexpected error occurred while opening the document 62.pdf\n",
      "Traceback (most recent call last):\n",
      "  File \"C:\\Users\\wurfil\\AppData\\Local\\Programs\\Python\\Python311\\Lib\\site-packages\\docling\\datamodel\\document.py\", line 120, in __init__\n",
      "    self._init_doc(backend, path_or_stream)\n",
      "  File \"C:\\Users\\wurfil\\AppData\\Local\\Programs\\Python\\Python311\\Lib\\site-packages\\docling\\datamodel\\document.py\", line 173, in _init_doc\n",
      "    self._backend = backend(self, path_or_stream=path_or_stream)\n",
      "                    ^^^^^^^^^^^^^^^^^^^^^^^^^^^^^^^^^^^^^^^^^^^^\n",
      "  File \"C:\\Users\\wurfil\\AppData\\Local\\Programs\\Python\\Python311\\Lib\\site-packages\\docling\\backend\\docling_parse_backend.py\", line 194, in __init__\n",
      "    self._pdoc = pdfium.PdfDocument(self.path_or_stream)\n",
      "                 ^^^^^^^^^^^^^^^^^^^^^^^^^^^^^^^^^^^^^^^\n",
      "  File \"C:\\Users\\wurfil\\AppData\\Local\\Programs\\Python\\Python311\\Lib\\site-packages\\pypdfium2\\_helpers\\document.py\", line 78, in __init__\n",
      "    self.raw, to_hold, to_close = _open_pdf(self._input, self._password, self._autoclose)\n",
      "                                  ^^^^^^^^^^^^^^^^^^^^^^^^^^^^^^^^^^^^^^^^^^^^^^^^^^^^^^^\n",
      "  File \"C:\\Users\\wurfil\\AppData\\Local\\Programs\\Python\\Python311\\Lib\\site-packages\\pypdfium2\\_helpers\\document.py\", line 678, in _open_pdf\n",
      "    raise PdfiumError(f\"Failed to load document (PDFium: {pdfium_i.ErrorToStr.get(err_code)}).\")\n",
      "pypdfium2._helpers.misc.PdfiumError: Failed to load document (PDFium: Data format error).\n",
      "ERROR:root:Ошибка при обработке .\\input\\62.pdf: Input document input\\62.pdf is not valid.\n",
      "ERROR:docling.datamodel.document:An unexpected error occurred while opening the document 63.pdf\n",
      "Traceback (most recent call last):\n",
      "  File \"C:\\Users\\wurfil\\AppData\\Local\\Programs\\Python\\Python311\\Lib\\site-packages\\docling\\datamodel\\document.py\", line 120, in __init__\n",
      "    self._init_doc(backend, path_or_stream)\n",
      "  File \"C:\\Users\\wurfil\\AppData\\Local\\Programs\\Python\\Python311\\Lib\\site-packages\\docling\\datamodel\\document.py\", line 173, in _init_doc\n",
      "    self._backend = backend(self, path_or_stream=path_or_stream)\n",
      "                    ^^^^^^^^^^^^^^^^^^^^^^^^^^^^^^^^^^^^^^^^^^^^\n",
      "  File \"C:\\Users\\wurfil\\AppData\\Local\\Programs\\Python\\Python311\\Lib\\site-packages\\docling\\backend\\docling_parse_backend.py\", line 194, in __init__\n",
      "    self._pdoc = pdfium.PdfDocument(self.path_or_stream)\n",
      "                 ^^^^^^^^^^^^^^^^^^^^^^^^^^^^^^^^^^^^^^^\n",
      "  File \"C:\\Users\\wurfil\\AppData\\Local\\Programs\\Python\\Python311\\Lib\\site-packages\\pypdfium2\\_helpers\\document.py\", line 78, in __init__\n",
      "    self.raw, to_hold, to_close = _open_pdf(self._input, self._password, self._autoclose)\n",
      "                                  ^^^^^^^^^^^^^^^^^^^^^^^^^^^^^^^^^^^^^^^^^^^^^^^^^^^^^^^\n",
      "  File \"C:\\Users\\wurfil\\AppData\\Local\\Programs\\Python\\Python311\\Lib\\site-packages\\pypdfium2\\_helpers\\document.py\", line 678, in _open_pdf\n",
      "    raise PdfiumError(f\"Failed to load document (PDFium: {pdfium_i.ErrorToStr.get(err_code)}).\")\n",
      "pypdfium2._helpers.misc.PdfiumError: Failed to load document (PDFium: Data format error).\n",
      "ERROR:root:Ошибка при обработке .\\input\\63.pdf: Input document input\\63.pdf is not valid.\n",
      "ERROR:docling.datamodel.document:An unexpected error occurred while opening the document 59.pdf\n",
      "Traceback (most recent call last):\n",
      "  File \"C:\\Users\\wurfil\\AppData\\Local\\Programs\\Python\\Python311\\Lib\\site-packages\\docling\\datamodel\\document.py\", line 120, in __init__\n",
      "    self._init_doc(backend, path_or_stream)\n",
      "  File \"C:\\Users\\wurfil\\AppData\\Local\\Programs\\Python\\Python311\\Lib\\site-packages\\docling\\datamodel\\document.py\", line 173, in _init_doc\n",
      "    self._backend = backend(self, path_or_stream=path_or_stream)\n",
      "                    ^^^^^^^^^^^^^^^^^^^^^^^^^^^^^^^^^^^^^^^^^^^^\n",
      "  File \"C:\\Users\\wurfil\\AppData\\Local\\Programs\\Python\\Python311\\Lib\\site-packages\\docling\\backend\\docling_parse_backend.py\", line 194, in __init__\n",
      "    self._pdoc = pdfium.PdfDocument(self.path_or_stream)\n",
      "                 ^^^^^^^^^^^^^^^^^^^^^^^^^^^^^^^^^^^^^^^\n",
      "  File \"C:\\Users\\wurfil\\AppData\\Local\\Programs\\Python\\Python311\\Lib\\site-packages\\pypdfium2\\_helpers\\document.py\", line 78, in __init__\n",
      "    self.raw, to_hold, to_close = _open_pdf(self._input, self._password, self._autoclose)\n",
      "                                  ^^^^^^^^^^^^^^^^^^^^^^^^^^^^^^^^^^^^^^^^^^^^^^^^^^^^^^^\n",
      "  File \"C:\\Users\\wurfil\\AppData\\Local\\Programs\\Python\\Python311\\Lib\\site-packages\\pypdfium2\\_helpers\\document.py\", line 678, in _open_pdf\n",
      "    raise PdfiumError(f\"Failed to load document (PDFium: {pdfium_i.ErrorToStr.get(err_code)}).\")\n",
      "pypdfium2._helpers.misc.PdfiumError: Failed to load document (PDFium: Data format error).\n",
      "ERROR:root:Ошибка при обработке .\\input\\59.pdf: Input document input\\59.pdf is not valid.\n",
      "ERROR:docling.datamodel.document:An unexpected error occurred while opening the document 66.pdf\n",
      "Traceback (most recent call last):\n",
      "  File \"C:\\Users\\wurfil\\AppData\\Local\\Programs\\Python\\Python311\\Lib\\site-packages\\docling\\datamodel\\document.py\", line 120, in __init__\n",
      "    self._init_doc(backend, path_or_stream)\n",
      "  File \"C:\\Users\\wurfil\\AppData\\Local\\Programs\\Python\\Python311\\Lib\\site-packages\\docling\\datamodel\\document.py\", line 173, in _init_doc\n",
      "    self._backend = backend(self, path_or_stream=path_or_stream)\n",
      "                    ^^^^^^^^^^^^^^^^^^^^^^^^^^^^^^^^^^^^^^^^^^^^\n",
      "  File \"C:\\Users\\wurfil\\AppData\\Local\\Programs\\Python\\Python311\\Lib\\site-packages\\docling\\backend\\docling_parse_backend.py\", line 194, in __init__\n",
      "    self._pdoc = pdfium.PdfDocument(self.path_or_stream)\n",
      "                 ^^^^^^^^^^^^^^^^^^^^^^^^^^^^^^^^^^^^^^^\n",
      "  File \"C:\\Users\\wurfil\\AppData\\Local\\Programs\\Python\\Python311\\Lib\\site-packages\\pypdfium2\\_helpers\\document.py\", line 78, in __init__\n",
      "    self.raw, to_hold, to_close = _open_pdf(self._input, self._password, self._autoclose)\n",
      "                                  ^^^^^^^^^^^^^^^^^^^^^^^^^^^^^^^^^^^^^^^^^^^^^^^^^^^^^^^\n",
      "  File \"C:\\Users\\wurfil\\AppData\\Local\\Programs\\Python\\Python311\\Lib\\site-packages\\pypdfium2\\_helpers\\document.py\", line 678, in _open_pdf\n",
      "    raise PdfiumError(f\"Failed to load document (PDFium: {pdfium_i.ErrorToStr.get(err_code)}).\")\n",
      "pypdfium2._helpers.misc.PdfiumError: Failed to load document (PDFium: Data format error).\n",
      "ERROR:root:Ошибка при обработке .\\input\\66.pdf: Input document input\\66.pdf is not valid.\n",
      "ERROR:docling.datamodel.document:An unexpected error occurred while opening the document 65.pdf\n",
      "Traceback (most recent call last):\n",
      "  File \"C:\\Users\\wurfil\\AppData\\Local\\Programs\\Python\\Python311\\Lib\\site-packages\\docling\\datamodel\\document.py\", line 120, in __init__\n",
      "    self._init_doc(backend, path_or_stream)\n",
      "  File \"C:\\Users\\wurfil\\AppData\\Local\\Programs\\Python\\Python311\\Lib\\site-packages\\docling\\datamodel\\document.py\", line 173, in _init_doc\n",
      "    self._backend = backend(self, path_or_stream=path_or_stream)\n",
      "                    ^^^^^^^^^^^^^^^^^^^^^^^^^^^^^^^^^^^^^^^^^^^^\n",
      "  File \"C:\\Users\\wurfil\\AppData\\Local\\Programs\\Python\\Python311\\Lib\\site-packages\\docling\\backend\\docling_parse_backend.py\", line 194, in __init__\n",
      "    self._pdoc = pdfium.PdfDocument(self.path_or_stream)\n",
      "                 ^^^^^^^^^^^^^^^^^^^^^^^^^^^^^^^^^^^^^^^\n",
      "  File \"C:\\Users\\wurfil\\AppData\\Local\\Programs\\Python\\Python311\\Lib\\site-packages\\pypdfium2\\_helpers\\document.py\", line 78, in __init__\n",
      "    self.raw, to_hold, to_close = _open_pdf(self._input, self._password, self._autoclose)\n",
      "                                  ^^^^^^^^^^^^^^^^^^^^^^^^^^^^^^^^^^^^^^^^^^^^^^^^^^^^^^^\n",
      "  File \"C:\\Users\\wurfil\\AppData\\Local\\Programs\\Python\\Python311\\Lib\\site-packages\\pypdfium2\\_helpers\\document.py\", line 678, in _open_pdf\n",
      "    raise PdfiumError(f\"Failed to load document (PDFium: {pdfium_i.ErrorToStr.get(err_code)}).\")\n",
      "pypdfium2._helpers.misc.PdfiumError: Failed to load document (PDFium: Data format error).\n",
      "ERROR:root:Ошибка при обработке .\\input\\65.pdf: Input document input\\65.pdf is not valid.\n",
      "ERROR:docling.datamodel.document:An unexpected error occurred while opening the document 68.pdf\n",
      "Traceback (most recent call last):\n",
      "  File \"C:\\Users\\wurfil\\AppData\\Local\\Programs\\Python\\Python311\\Lib\\site-packages\\docling\\datamodel\\document.py\", line 120, in __init__\n",
      "    self._init_doc(backend, path_or_stream)\n",
      "  File \"C:\\Users\\wurfil\\AppData\\Local\\Programs\\Python\\Python311\\Lib\\site-packages\\docling\\datamodel\\document.py\", line 173, in _init_doc\n",
      "    self._backend = backend(self, path_or_stream=path_or_stream)\n",
      "                    ^^^^^^^^^^^^^^^^^^^^^^^^^^^^^^^^^^^^^^^^^^^^\n",
      "  File \"C:\\Users\\wurfil\\AppData\\Local\\Programs\\Python\\Python311\\Lib\\site-packages\\docling\\backend\\docling_parse_backend.py\", line 194, in __init__\n",
      "    self._pdoc = pdfium.PdfDocument(self.path_or_stream)\n",
      "                 ^^^^^^^^^^^^^^^^^^^^^^^^^^^^^^^^^^^^^^^\n",
      "  File \"C:\\Users\\wurfil\\AppData\\Local\\Programs\\Python\\Python311\\Lib\\site-packages\\pypdfium2\\_helpers\\document.py\", line 78, in __init__\n",
      "    self.raw, to_hold, to_close = _open_pdf(self._input, self._password, self._autoclose)\n",
      "                                  ^^^^^^^^^^^^^^^^^^^^^^^^^^^^^^^^^^^^^^^^^^^^^^^^^^^^^^^\n",
      "  File \"C:\\Users\\wurfil\\AppData\\Local\\Programs\\Python\\Python311\\Lib\\site-packages\\pypdfium2\\_helpers\\document.py\", line 678, in _open_pdf\n",
      "    raise PdfiumError(f\"Failed to load document (PDFium: {pdfium_i.ErrorToStr.get(err_code)}).\")\n",
      "pypdfium2._helpers.misc.PdfiumError: Failed to load document (PDFium: Data format error).\n",
      "ERROR:root:Ошибка при обработке .\\input\\68.pdf: Input document input\\68.pdf is not valid.\n",
      "ERROR:docling.datamodel.document:An unexpected error occurred while opening the document 46.pdf\n",
      "Traceback (most recent call last):\n",
      "  File \"C:\\Users\\wurfil\\AppData\\Local\\Programs\\Python\\Python311\\Lib\\site-packages\\docling\\datamodel\\document.py\", line 120, in __init__\n",
      "    self._init_doc(backend, path_or_stream)\n",
      "  File \"C:\\Users\\wurfil\\AppData\\Local\\Programs\\Python\\Python311\\Lib\\site-packages\\docling\\datamodel\\document.py\", line 173, in _init_doc\n",
      "    self._backend = backend(self, path_or_stream=path_or_stream)\n",
      "                    ^^^^^^^^^^^^^^^^^^^^^^^^^^^^^^^^^^^^^^^^^^^^\n",
      "  File \"C:\\Users\\wurfil\\AppData\\Local\\Programs\\Python\\Python311\\Lib\\site-packages\\docling\\backend\\docling_parse_backend.py\", line 194, in __init__\n",
      "    self._pdoc = pdfium.PdfDocument(self.path_or_stream)\n",
      "                 ^^^^^^^^^^^^^^^^^^^^^^^^^^^^^^^^^^^^^^^\n",
      "  File \"C:\\Users\\wurfil\\AppData\\Local\\Programs\\Python\\Python311\\Lib\\site-packages\\pypdfium2\\_helpers\\document.py\", line 78, in __init__\n",
      "    self.raw, to_hold, to_close = _open_pdf(self._input, self._password, self._autoclose)\n",
      "                                  ^^^^^^^^^^^^^^^^^^^^^^^^^^^^^^^^^^^^^^^^^^^^^^^^^^^^^^^\n",
      "  File \"C:\\Users\\wurfil\\AppData\\Local\\Programs\\Python\\Python311\\Lib\\site-packages\\pypdfium2\\_helpers\\document.py\", line 678, in _open_pdf\n",
      "    raise PdfiumError(f\"Failed to load document (PDFium: {pdfium_i.ErrorToStr.get(err_code)}).\")\n",
      "pypdfium2._helpers.misc.PdfiumError: Failed to load document (PDFium: Data format error).\n",
      "ERROR:root:Ошибка при обработке .\\input\\46.pdf: Input document input\\46.pdf is not valid.\n",
      "ERROR:docling.datamodel.document:An unexpected error occurred while opening the document 7.pdf\n",
      "Traceback (most recent call last):\n",
      "  File \"C:\\Users\\wurfil\\AppData\\Local\\Programs\\Python\\Python311\\Lib\\site-packages\\docling\\datamodel\\document.py\", line 120, in __init__\n",
      "    self._init_doc(backend, path_or_stream)\n",
      "  File \"C:\\Users\\wurfil\\AppData\\Local\\Programs\\Python\\Python311\\Lib\\site-packages\\docling\\datamodel\\document.py\", line 173, in _init_doc\n",
      "    self._backend = backend(self, path_or_stream=path_or_stream)\n",
      "                    ^^^^^^^^^^^^^^^^^^^^^^^^^^^^^^^^^^^^^^^^^^^^\n",
      "  File \"C:\\Users\\wurfil\\AppData\\Local\\Programs\\Python\\Python311\\Lib\\site-packages\\docling\\backend\\docling_parse_backend.py\", line 194, in __init__\n",
      "    self._pdoc = pdfium.PdfDocument(self.path_or_stream)\n",
      "                 ^^^^^^^^^^^^^^^^^^^^^^^^^^^^^^^^^^^^^^^\n",
      "  File \"C:\\Users\\wurfil\\AppData\\Local\\Programs\\Python\\Python311\\Lib\\site-packages\\pypdfium2\\_helpers\\document.py\", line 78, in __init__\n",
      "    self.raw, to_hold, to_close = _open_pdf(self._input, self._password, self._autoclose)\n",
      "                                  ^^^^^^^^^^^^^^^^^^^^^^^^^^^^^^^^^^^^^^^^^^^^^^^^^^^^^^^\n",
      "  File \"C:\\Users\\wurfil\\AppData\\Local\\Programs\\Python\\Python311\\Lib\\site-packages\\pypdfium2\\_helpers\\document.py\", line 678, in _open_pdf\n",
      "    raise PdfiumError(f\"Failed to load document (PDFium: {pdfium_i.ErrorToStr.get(err_code)}).\")\n",
      "pypdfium2._helpers.misc.PdfiumError: Failed to load document (PDFium: Data format error).\n",
      "ERROR:root:Ошибка при обработке .\\input\\7.pdf: Input document input\\7.pdf is not valid.\n",
      "ERROR:docling.datamodel.document:An unexpected error occurred while opening the document 69.pdf\n",
      "Traceback (most recent call last):\n",
      "  File \"C:\\Users\\wurfil\\AppData\\Local\\Programs\\Python\\Python311\\Lib\\site-packages\\docling\\datamodel\\document.py\", line 120, in __init__\n",
      "    self._init_doc(backend, path_or_stream)\n",
      "  File \"C:\\Users\\wurfil\\AppData\\Local\\Programs\\Python\\Python311\\Lib\\site-packages\\docling\\datamodel\\document.py\", line 173, in _init_doc\n",
      "    self._backend = backend(self, path_or_stream=path_or_stream)\n",
      "                    ^^^^^^^^^^^^^^^^^^^^^^^^^^^^^^^^^^^^^^^^^^^^\n",
      "  File \"C:\\Users\\wurfil\\AppData\\Local\\Programs\\Python\\Python311\\Lib\\site-packages\\docling\\backend\\docling_parse_backend.py\", line 194, in __init__\n",
      "    self._pdoc = pdfium.PdfDocument(self.path_or_stream)\n",
      "                 ^^^^^^^^^^^^^^^^^^^^^^^^^^^^^^^^^^^^^^^\n",
      "  File \"C:\\Users\\wurfil\\AppData\\Local\\Programs\\Python\\Python311\\Lib\\site-packages\\pypdfium2\\_helpers\\document.py\", line 78, in __init__\n",
      "    self.raw, to_hold, to_close = _open_pdf(self._input, self._password, self._autoclose)\n",
      "                                  ^^^^^^^^^^^^^^^^^^^^^^^^^^^^^^^^^^^^^^^^^^^^^^^^^^^^^^^\n",
      "  File \"C:\\Users\\wurfil\\AppData\\Local\\Programs\\Python\\Python311\\Lib\\site-packages\\pypdfium2\\_helpers\\document.py\", line 678, in _open_pdf\n",
      "    raise PdfiumError(f\"Failed to load document (PDFium: {pdfium_i.ErrorToStr.get(err_code)}).\")\n",
      "pypdfium2._helpers.misc.PdfiumError: Failed to load document (PDFium: Data format error).\n",
      "ERROR:root:Ошибка при обработке .\\input\\69.pdf: Input document input\\69.pdf is not valid.\n",
      "ERROR:docling.datamodel.document:An unexpected error occurred while opening the document 44.pdf\n",
      "Traceback (most recent call last):\n",
      "  File \"C:\\Users\\wurfil\\AppData\\Local\\Programs\\Python\\Python311\\Lib\\site-packages\\docling\\datamodel\\document.py\", line 120, in __init__\n",
      "    self._init_doc(backend, path_or_stream)\n",
      "  File \"C:\\Users\\wurfil\\AppData\\Local\\Programs\\Python\\Python311\\Lib\\site-packages\\docling\\datamodel\\document.py\", line 173, in _init_doc\n",
      "    self._backend = backend(self, path_or_stream=path_or_stream)\n",
      "                    ^^^^^^^^^^^^^^^^^^^^^^^^^^^^^^^^^^^^^^^^^^^^\n",
      "  File \"C:\\Users\\wurfil\\AppData\\Local\\Programs\\Python\\Python311\\Lib\\site-packages\\docling\\backend\\docling_parse_backend.py\", line 194, in __init__\n",
      "    self._pdoc = pdfium.PdfDocument(self.path_or_stream)\n",
      "                 ^^^^^^^^^^^^^^^^^^^^^^^^^^^^^^^^^^^^^^^\n",
      "  File \"C:\\Users\\wurfil\\AppData\\Local\\Programs\\Python\\Python311\\Lib\\site-packages\\pypdfium2\\_helpers\\document.py\", line 78, in __init__\n",
      "    self.raw, to_hold, to_close = _open_pdf(self._input, self._password, self._autoclose)\n",
      "                                  ^^^^^^^^^^^^^^^^^^^^^^^^^^^^^^^^^^^^^^^^^^^^^^^^^^^^^^^\n",
      "  File \"C:\\Users\\wurfil\\AppData\\Local\\Programs\\Python\\Python311\\Lib\\site-packages\\pypdfium2\\_helpers\\document.py\", line 678, in _open_pdf\n",
      "    raise PdfiumError(f\"Failed to load document (PDFium: {pdfium_i.ErrorToStr.get(err_code)}).\")\n",
      "pypdfium2._helpers.misc.PdfiumError: Failed to load document (PDFium: Data format error).\n",
      "ERROR:root:Ошибка при обработке .\\input\\44.pdf: Input document input\\44.pdf is not valid.\n",
      "ERROR:docling.datamodel.document:An unexpected error occurred while opening the document 9.pdf\n",
      "Traceback (most recent call last):\n",
      "  File \"C:\\Users\\wurfil\\AppData\\Local\\Programs\\Python\\Python311\\Lib\\site-packages\\docling\\datamodel\\document.py\", line 120, in __init__\n",
      "    self._init_doc(backend, path_or_stream)\n",
      "  File \"C:\\Users\\wurfil\\AppData\\Local\\Programs\\Python\\Python311\\Lib\\site-packages\\docling\\datamodel\\document.py\", line 173, in _init_doc\n",
      "    self._backend = backend(self, path_or_stream=path_or_stream)\n",
      "                    ^^^^^^^^^^^^^^^^^^^^^^^^^^^^^^^^^^^^^^^^^^^^\n",
      "  File \"C:\\Users\\wurfil\\AppData\\Local\\Programs\\Python\\Python311\\Lib\\site-packages\\docling\\backend\\docling_parse_backend.py\", line 194, in __init__\n",
      "    self._pdoc = pdfium.PdfDocument(self.path_or_stream)\n",
      "                 ^^^^^^^^^^^^^^^^^^^^^^^^^^^^^^^^^^^^^^^\n",
      "  File \"C:\\Users\\wurfil\\AppData\\Local\\Programs\\Python\\Python311\\Lib\\site-packages\\pypdfium2\\_helpers\\document.py\", line 78, in __init__\n",
      "    self.raw, to_hold, to_close = _open_pdf(self._input, self._password, self._autoclose)\n",
      "                                  ^^^^^^^^^^^^^^^^^^^^^^^^^^^^^^^^^^^^^^^^^^^^^^^^^^^^^^^\n",
      "  File \"C:\\Users\\wurfil\\AppData\\Local\\Programs\\Python\\Python311\\Lib\\site-packages\\pypdfium2\\_helpers\\document.py\", line 678, in _open_pdf\n",
      "    raise PdfiumError(f\"Failed to load document (PDFium: {pdfium_i.ErrorToStr.get(err_code)}).\")\n",
      "pypdfium2._helpers.misc.PdfiumError: Failed to load document (PDFium: Data format error).\n",
      "ERROR:root:Ошибка при обработке .\\input\\9.pdf: Input document input\\9.pdf is not valid.\n",
      "ERROR:docling.datamodel.document:An unexpected error occurred while opening the document 67.pdf\n",
      "Traceback (most recent call last):\n",
      "  File \"C:\\Users\\wurfil\\AppData\\Local\\Programs\\Python\\Python311\\Lib\\site-packages\\docling\\datamodel\\document.py\", line 120, in __init__\n",
      "    self._init_doc(backend, path_or_stream)\n",
      "  File \"C:\\Users\\wurfil\\AppData\\Local\\Programs\\Python\\Python311\\Lib\\site-packages\\docling\\datamodel\\document.py\", line 173, in _init_doc\n",
      "    self._backend = backend(self, path_or_stream=path_or_stream)\n",
      "                    ^^^^^^^^^^^^^^^^^^^^^^^^^^^^^^^^^^^^^^^^^^^^\n",
      "  File \"C:\\Users\\wurfil\\AppData\\Local\\Programs\\Python\\Python311\\Lib\\site-packages\\docling\\backend\\docling_parse_backend.py\", line 194, in __init__\n",
      "    self._pdoc = pdfium.PdfDocument(self.path_or_stream)\n",
      "                 ^^^^^^^^^^^^^^^^^^^^^^^^^^^^^^^^^^^^^^^\n",
      "  File \"C:\\Users\\wurfil\\AppData\\Local\\Programs\\Python\\Python311\\Lib\\site-packages\\pypdfium2\\_helpers\\document.py\", line 78, in __init__\n",
      "    self.raw, to_hold, to_close = _open_pdf(self._input, self._password, self._autoclose)\n",
      "                                  ^^^^^^^^^^^^^^^^^^^^^^^^^^^^^^^^^^^^^^^^^^^^^^^^^^^^^^^\n",
      "  File \"C:\\Users\\wurfil\\AppData\\Local\\Programs\\Python\\Python311\\Lib\\site-packages\\pypdfium2\\_helpers\\document.py\", line 678, in _open_pdf\n",
      "    raise PdfiumError(f\"Failed to load document (PDFium: {pdfium_i.ErrorToStr.get(err_code)}).\")\n",
      "pypdfium2._helpers.misc.PdfiumError: Failed to load document (PDFium: Data format error).\n",
      "ERROR:root:Ошибка при обработке .\\input\\67.pdf: Input document input\\67.pdf is not valid.\n",
      "ERROR:docling.datamodel.document:An unexpected error occurred while opening the document 8.pdf\n",
      "Traceback (most recent call last):\n",
      "  File \"C:\\Users\\wurfil\\AppData\\Local\\Programs\\Python\\Python311\\Lib\\site-packages\\docling\\datamodel\\document.py\", line 120, in __init__\n",
      "    self._init_doc(backend, path_or_stream)\n",
      "  File \"C:\\Users\\wurfil\\AppData\\Local\\Programs\\Python\\Python311\\Lib\\site-packages\\docling\\datamodel\\document.py\", line 173, in _init_doc\n",
      "    self._backend = backend(self, path_or_stream=path_or_stream)\n",
      "                    ^^^^^^^^^^^^^^^^^^^^^^^^^^^^^^^^^^^^^^^^^^^^\n",
      "  File \"C:\\Users\\wurfil\\AppData\\Local\\Programs\\Python\\Python311\\Lib\\site-packages\\docling\\backend\\docling_parse_backend.py\", line 194, in __init__\n",
      "    self._pdoc = pdfium.PdfDocument(self.path_or_stream)\n",
      "                 ^^^^^^^^^^^^^^^^^^^^^^^^^^^^^^^^^^^^^^^\n",
      "  File \"C:\\Users\\wurfil\\AppData\\Local\\Programs\\Python\\Python311\\Lib\\site-packages\\pypdfium2\\_helpers\\document.py\", line 78, in __init__\n",
      "    self.raw, to_hold, to_close = _open_pdf(self._input, self._password, self._autoclose)\n",
      "                                  ^^^^^^^^^^^^^^^^^^^^^^^^^^^^^^^^^^^^^^^^^^^^^^^^^^^^^^^\n",
      "  File \"C:\\Users\\wurfil\\AppData\\Local\\Programs\\Python\\Python311\\Lib\\site-packages\\pypdfium2\\_helpers\\document.py\", line 678, in _open_pdf\n",
      "    raise PdfiumError(f\"Failed to load document (PDFium: {pdfium_i.ErrorToStr.get(err_code)}).\")\n",
      "pypdfium2._helpers.misc.PdfiumError: Failed to load document (PDFium: Data format error).\n",
      "ERROR:root:Ошибка при обработке .\\input\\8.pdf: Input document input\\8.pdf is not valid.\n",
      "ERROR:docling.datamodel.document:An unexpected error occurred while opening the document 64.pdf\n",
      "Traceback (most recent call last):\n",
      "  File \"C:\\Users\\wurfil\\AppData\\Local\\Programs\\Python\\Python311\\Lib\\site-packages\\docling\\datamodel\\document.py\", line 120, in __init__\n",
      "    self._init_doc(backend, path_or_stream)\n",
      "  File \"C:\\Users\\wurfil\\AppData\\Local\\Programs\\Python\\Python311\\Lib\\site-packages\\docling\\datamodel\\document.py\", line 173, in _init_doc\n",
      "    self._backend = backend(self, path_or_stream=path_or_stream)\n",
      "                    ^^^^^^^^^^^^^^^^^^^^^^^^^^^^^^^^^^^^^^^^^^^^\n",
      "  File \"C:\\Users\\wurfil\\AppData\\Local\\Programs\\Python\\Python311\\Lib\\site-packages\\docling\\backend\\docling_parse_backend.py\", line 194, in __init__\n",
      "    self._pdoc = pdfium.PdfDocument(self.path_or_stream)\n",
      "                 ^^^^^^^^^^^^^^^^^^^^^^^^^^^^^^^^^^^^^^^\n",
      "  File \"C:\\Users\\wurfil\\AppData\\Local\\Programs\\Python\\Python311\\Lib\\site-packages\\pypdfium2\\_helpers\\document.py\", line 78, in __init__\n",
      "    self.raw, to_hold, to_close = _open_pdf(self._input, self._password, self._autoclose)\n",
      "                                  ^^^^^^^^^^^^^^^^^^^^^^^^^^^^^^^^^^^^^^^^^^^^^^^^^^^^^^^\n",
      "  File \"C:\\Users\\wurfil\\AppData\\Local\\Programs\\Python\\Python311\\Lib\\site-packages\\pypdfium2\\_helpers\\document.py\", line 678, in _open_pdf\n",
      "    raise PdfiumError(f\"Failed to load document (PDFium: {pdfium_i.ErrorToStr.get(err_code)}).\")\n",
      "pypdfium2._helpers.misc.PdfiumError: Failed to load document (PDFium: Data format error).\n",
      "ERROR:root:Ошибка при обработке .\\input\\64.pdf: Input document input\\64.pdf is not valid.\n"
     ]
    }
   ],
   "source": [
    "res = process_documents(files)"
   ]
  },
  {
   "cell_type": "code",
   "execution_count": null,
   "id": "f6119529-7343-4a64-a1e4-fd15bb2236a1",
   "metadata": {},
   "outputs": [],
   "source": [
    "# import pandas as pd\n",
    "import pandas as pd\n",
    "\n",
    "df = pd.DataFrame(rows)\n",
    "df.to_csv('stucture_data.csv')"
   ]
  },
  {
   "cell_type": "code",
   "execution_count": null,
   "id": "6c26e001-9f2c-4c59-9887-215ee9a37d8b",
   "metadata": {},
   "outputs": [],
   "source": []
  }
 ],
 "metadata": {
  "kernelspec": {
   "display_name": "Python 3 (ipykernel)",
   "language": "python",
   "name": "python3"
  },
  "language_info": {
   "codemirror_mode": {
    "name": "ipython",
    "version": 3
   },
   "file_extension": ".py",
   "mimetype": "text/x-python",
   "name": "python",
   "nbconvert_exporter": "python",
   "pygments_lexer": "ipython3",
   "version": "3.11.9"
  }
 },
 "nbformat": 4,
 "nbformat_minor": 5
}
